WARNING 2024-12-29 12:16:45,776 Forbidden: /accounts/users/me/get-myname/
WARNING 2024-12-29 12:16:45,776 Forbidden: /accounts/users/me/get-myname/
WARNING 2024-12-29 12:17:47,728 Not Found: /favicon.ico
WARNING 2024-12-29 12:17:47,728 Not Found: /favicon.ico
WARNING 2024-12-29 12:18:02,190 Forbidden: /accounts/users/me/get-myname/
WARNING 2024-12-29 12:18:02,190 Forbidden: /accounts/users/me/get-myname/
WARNING 2024-12-29 12:25:35,248 Forbidden: /accounts/users/me/get-myname/
WARNING 2024-12-29 12:25:35,248 Forbidden: /accounts/users/me/get-myname/
WARNING 2024-12-29 12:25:38,057 Forbidden: /accounts/users/me/get-myname/
WARNING 2024-12-29 12:25:38,057 Forbidden: /accounts/users/me/get-myname/
WARNING 2024-12-29 12:25:38,062 Not Found: /favicon.ico
WARNING 2024-12-29 12:25:38,062 Not Found: /favicon.ico
WARNING 2024-12-29 12:25:38,875 Forbidden: /accounts/users/me/get-myname/
WARNING 2024-12-29 12:25:38,875 Forbidden: /accounts/users/me/get-myname/
WARNING 2024-12-29 12:26:48,411 Forbidden: /accounts/users/me/get-myname/
WARNING 2024-12-29 12:26:48,411 Forbidden: /accounts/users/me/get-myname/
WARNING 2024-12-29 12:31:58,206 Not Found: /favicon.ico
WARNING 2024-12-29 12:31:58,206 Not Found: /favicon.ico
WARNING 2024-12-29 13:14:41,192 Forbidden: /accounts/users/me/get-myname/
WARNING 2024-12-29 13:14:41,192 Forbidden: /accounts/users/me/get-myname/
WARNING 2024-12-29 13:14:41,927 Forbidden: /accounts/users/me/get-myname/
WARNING 2024-12-29 13:14:41,927 Forbidden: /accounts/users/me/get-myname/
WARNING 2024-12-29 13:14:47,647 Forbidden: /accounts/users/me/get-myname/
WARNING 2024-12-29 13:14:47,647 Forbidden: /accounts/users/me/get-myname/
WARNING 2024-12-29 13:15:07,733 Not Found: /favicon.ico
WARNING 2024-12-29 13:15:07,733 Not Found: /favicon.ico
WARNING 2024-12-29 13:25:53,987 Forbidden: /accounts/users/me/get-myname/
WARNING 2024-12-29 13:25:53,987 Forbidden: /accounts/users/me/get-myname/
WARNING 2024-12-29 13:26:03,456 Forbidden: /accounts/users/me/get-myname/
WARNING 2024-12-29 13:26:03,456 Forbidden: /accounts/users/me/get-myname/
WARNING 2024-12-29 13:26:11,845 Forbidden: /accounts/users/me/get-myname/
WARNING 2024-12-29 13:26:11,845 Forbidden: /accounts/users/me/get-myname/
WARNING 2024-12-29 13:26:24,474 Forbidden: /accounts/users/me/get-myname/
WARNING 2024-12-29 13:26:24,474 Forbidden: /accounts/users/me/get-myname/
WARNING 2024-12-29 13:26:40,160 Forbidden: /accounts/users/me/get-myname/
WARNING 2024-12-29 13:26:40,160 Forbidden: /accounts/users/me/get-myname/
WARNING 2024-12-29 13:27:04,560 Forbidden: /accounts/users/me/get-myname/
WARNING 2024-12-29 13:27:04,560 Forbidden: /accounts/users/me/get-myname/
WARNING 2024-12-29 13:27:15,303 Forbidden: /accounts/users/me/get-myname/
WARNING 2024-12-29 13:27:15,303 Forbidden: /accounts/users/me/get-myname/
WARNING 2024-12-29 13:27:28,042 Forbidden: /accounts/users/me/get-myname/
WARNING 2024-12-29 13:27:28,042 Forbidden: /accounts/users/me/get-myname/
WARNING 2024-12-29 13:27:49,582 Forbidden: /accounts/users/me/get-myname/
WARNING 2024-12-29 13:27:49,582 Forbidden: /accounts/users/me/get-myname/
WARNING 2024-12-29 13:28:02,220 Forbidden: /accounts/users/me/get-myname/
WARNING 2024-12-29 13:28:02,220 Forbidden: /accounts/users/me/get-myname/
WARNING 2024-12-29 13:28:29,445 Forbidden: /accounts/users/me/get-myname/
WARNING 2024-12-29 13:28:29,445 Forbidden: /accounts/users/me/get-myname/
WARNING 2024-12-29 13:28:42,787 Forbidden: /accounts/users/me/get-myname/
WARNING 2024-12-29 13:28:42,787 Forbidden: /accounts/users/me/get-myname/
WARNING 2024-12-29 13:29:50,821 Forbidden: /accounts/users/me/get-myname/
WARNING 2024-12-29 13:29:50,821 Forbidden: /accounts/users/me/get-myname/
WARNING 2024-12-29 13:30:24,887 Forbidden: /accounts/users/me/get-myname/
WARNING 2024-12-29 13:30:24,887 Forbidden: /accounts/users/me/get-myname/
WARNING 2024-12-29 13:30:40,490 Forbidden: /accounts/users/me/get-myname/
WARNING 2024-12-29 13:30:40,490 Forbidden: /accounts/users/me/get-myname/
WARNING 2024-12-29 13:30:54,038 Forbidden: /accounts/users/me/get-myname/
WARNING 2024-12-29 13:30:54,038 Forbidden: /accounts/users/me/get-myname/
WARNING 2024-12-29 13:31:29,155 Forbidden: /accounts/users/me/get-myname/
WARNING 2024-12-29 13:31:29,155 Forbidden: /accounts/users/me/get-myname/
WARNING 2024-12-29 13:31:40,969 Forbidden: /accounts/users/me/get-myname/
WARNING 2024-12-29 13:31:40,969 Forbidden: /accounts/users/me/get-myname/
WARNING 2024-12-29 13:33:46,929 Forbidden: /accounts/users/me/get-myname/
WARNING 2024-12-29 13:33:46,929 Forbidden: /accounts/users/me/get-myname/
WARNING 2024-12-29 13:37:39,241 Forbidden: /accounts/users/me/get-myname/
WARNING 2024-12-29 13:37:39,241 Forbidden: /accounts/users/me/get-myname/
WARNING 2024-12-29 13:38:10,829 Forbidden: /accounts/users/me/get-myname/
WARNING 2024-12-29 13:38:10,829 Forbidden: /accounts/users/me/get-myname/
WARNING 2024-12-29 13:38:40,229 Forbidden: /accounts/users/me/get-myname/
WARNING 2024-12-29 13:38:40,229 Forbidden: /accounts/users/me/get-myname/
WARNING 2024-12-29 13:38:51,393 Forbidden: /accounts/users/me/get-myname/
WARNING 2024-12-29 13:38:51,393 Forbidden: /accounts/users/me/get-myname/
WARNING 2024-12-29 13:39:20,155 Forbidden: /accounts/users/me/get-myname/
WARNING 2024-12-29 13:39:20,155 Forbidden: /accounts/users/me/get-myname/
WARNING 2024-12-29 13:39:24,882 Forbidden: /accounts/users/me/get-myname/
WARNING 2024-12-29 13:39:24,882 Forbidden: /accounts/users/me/get-myname/
WARNING 2024-12-29 13:39:24,895 Not Found: /favicon.ico
WARNING 2024-12-29 13:39:24,895 Not Found: /favicon.ico
WARNING 2024-12-29 13:39:48,727 Forbidden: /accounts/users/me/get-myname/
WARNING 2024-12-29 13:39:48,727 Forbidden: /accounts/users/me/get-myname/
WARNING 2024-12-29 13:39:58,093 Forbidden: /accounts/users/me/get-myname/
WARNING 2024-12-29 13:39:58,093 Forbidden: /accounts/users/me/get-myname/
WARNING 2024-12-29 13:42:15,554 Forbidden: /accounts/users/me/get-myname/
WARNING 2024-12-29 13:42:15,554 Forbidden: /accounts/users/me/get-myname/
WARNING 2024-12-29 13:42:17,881 Forbidden: /accounts/users/me/get-myname/
WARNING 2024-12-29 13:42:17,881 Forbidden: /accounts/users/me/get-myname/
WARNING 2024-12-29 13:43:14,775 Forbidden: /accounts/users/me/get-myname/
WARNING 2024-12-29 13:43:14,775 Forbidden: /accounts/users/me/get-myname/
WARNING 2024-12-29 13:43:26,334 Forbidden: /accounts/users/me/get-myname/
WARNING 2024-12-29 13:43:26,334 Forbidden: /accounts/users/me/get-myname/
WARNING 2024-12-29 13:43:39,048 Forbidden: /accounts/users/me/get-myname/
WARNING 2024-12-29 13:43:39,048 Forbidden: /accounts/users/me/get-myname/
WARNING 2024-12-29 13:43:47,568 Forbidden: /accounts/users/me/get-myname/
WARNING 2024-12-29 13:43:47,568 Forbidden: /accounts/users/me/get-myname/
WARNING 2024-12-29 13:43:54,733 Forbidden: /accounts/users/me/get-myname/
WARNING 2024-12-29 13:43:54,733 Forbidden: /accounts/users/me/get-myname/
WARNING 2024-12-29 13:44:04,377 Forbidden: /accounts/users/me/get-myname/
WARNING 2024-12-29 13:44:04,377 Forbidden: /accounts/users/me/get-myname/
WARNING 2024-12-29 14:10:05,348 Forbidden: /accounts/users/me/get-myname/
WARNING 2024-12-29 14:10:05,348 Forbidden: /accounts/users/me/get-myname/
WARNING 2024-12-29 14:47:35,821 Forbidden: /accounts/users/me/get-myname/
WARNING 2024-12-29 14:47:35,821 Forbidden: /accounts/users/me/get-myname/
WARNING 2024-12-29 14:47:53,573 Not Found: /favicon.ico
WARNING 2024-12-29 14:47:53,573 Not Found: /favicon.ico
WARNING 2024-12-29 16:26:54,939 Forbidden: /accounts/users/me/get-myname/
WARNING 2024-12-29 16:26:54,939 Forbidden: /accounts/users/me/get-myname/
WARNING 2024-12-29 16:26:56,376 Forbidden: /accounts/users/me/get-myname/
WARNING 2024-12-29 16:26:56,376 Forbidden: /accounts/users/me/get-myname/
WARNING 2024-12-29 16:26:56,565 Forbidden: /accounts/users/me/get-myname/
WARNING 2024-12-29 16:26:56,565 Forbidden: /accounts/users/me/get-myname/
WARNING 2024-12-29 16:26:56,751 Forbidden: /accounts/users/me/get-myname/
WARNING 2024-12-29 16:26:56,751 Forbidden: /accounts/users/me/get-myname/
WARNING 2024-12-29 16:27:05,535 Forbidden: /accounts/users/me/get-myname/
WARNING 2024-12-29 16:27:05,535 Forbidden: /accounts/users/me/get-myname/
ERROR 2025-01-07 12:52:21,939 Invalid HTTP_HOST header: '10.12.8.3'. You may need to add '10.12.8.3' to ALLOWED_HOSTS.
Traceback (most recent call last):
  File "/usr/local/lib/python3.11/site-packages/asgiref/sync.py", line 518, in thread_handler
    raise exc_info[1]
  File "/usr/local/lib/python3.11/site-packages/django/core/handlers/exception.py", line 42, in inner
    response = await get_response(request)
               ^^^^^^^^^^^^^^^^^^^^^^^^^^^
  File "/usr/local/lib/python3.11/site-packages/django/utils/deprecation.py", line 141, in __acall__
    response = await sync_to_async(
               ^^^^^^^^^^^^^^^^^^^^
  File "/usr/local/lib/python3.11/site-packages/asgiref/sync.py", line 468, in __call__
    ret = await asyncio.shield(exec_coro)
          ^^^^^^^^^^^^^^^^^^^^^^^^^^^^^^^
  File "/usr/local/lib/python3.11/concurrent/futures/thread.py", line 58, in run
    result = self.fn(*self.args, **self.kwargs)
             ^^^^^^^^^^^^^^^^^^^^^^^^^^^^^^^^^^
  File "/usr/local/lib/python3.11/site-packages/asgiref/sync.py", line 522, in thread_handler
    return func(*args, **kwargs)
           ^^^^^^^^^^^^^^^^^^^^^
  File "/usr/local/lib/python3.11/site-packages/django/middleware/common.py", line 48, in process_request
    host = request.get_host()
           ^^^^^^^^^^^^^^^^^^
  File "/usr/local/lib/python3.11/site-packages/django/http/request.py", line 151, in get_host
    raise DisallowedHost(msg)
django.core.exceptions.DisallowedHost: Invalid HTTP_HOST header: '10.12.8.3'. You may need to add '10.12.8.3' to ALLOWED_HOSTS.
ERROR 2025-01-07 12:52:21,939 Invalid HTTP_HOST header: '10.12.8.3'. You may need to add '10.12.8.3' to ALLOWED_HOSTS.
Traceback (most recent call last):
  File "/usr/local/lib/python3.11/site-packages/asgiref/sync.py", line 518, in thread_handler
    raise exc_info[1]
  File "/usr/local/lib/python3.11/site-packages/django/core/handlers/exception.py", line 42, in inner
    response = await get_response(request)
               ^^^^^^^^^^^^^^^^^^^^^^^^^^^
  File "/usr/local/lib/python3.11/site-packages/django/utils/deprecation.py", line 141, in __acall__
    response = await sync_to_async(
               ^^^^^^^^^^^^^^^^^^^^
  File "/usr/local/lib/python3.11/site-packages/asgiref/sync.py", line 468, in __call__
    ret = await asyncio.shield(exec_coro)
          ^^^^^^^^^^^^^^^^^^^^^^^^^^^^^^^
  File "/usr/local/lib/python3.11/concurrent/futures/thread.py", line 58, in run
    result = self.fn(*self.args, **self.kwargs)
             ^^^^^^^^^^^^^^^^^^^^^^^^^^^^^^^^^^
  File "/usr/local/lib/python3.11/site-packages/asgiref/sync.py", line 522, in thread_handler
    return func(*args, **kwargs)
           ^^^^^^^^^^^^^^^^^^^^^
  File "/usr/local/lib/python3.11/site-packages/django/middleware/common.py", line 48, in process_request
    host = request.get_host()
           ^^^^^^^^^^^^^^^^^^
  File "/usr/local/lib/python3.11/site-packages/django/http/request.py", line 151, in get_host
    raise DisallowedHost(msg)
django.core.exceptions.DisallowedHost: Invalid HTTP_HOST header: '10.12.8.3'. You may need to add '10.12.8.3' to ALLOWED_HOSTS.
WARNING 2025-01-07 12:52:22,000 Bad Request: /
WARNING 2025-01-07 12:52:22,000 Bad Request: /
ERROR 2025-01-07 12:52:22,019 Invalid HTTP_HOST header: '10.12.8.3'. You may need to add '10.12.8.3' to ALLOWED_HOSTS.
Traceback (most recent call last):
  File "/usr/local/lib/python3.11/site-packages/asgiref/sync.py", line 518, in thread_handler
    raise exc_info[1]
  File "/usr/local/lib/python3.11/site-packages/django/core/handlers/exception.py", line 42, in inner
    response = await get_response(request)
               ^^^^^^^^^^^^^^^^^^^^^^^^^^^
  File "/usr/local/lib/python3.11/site-packages/django/utils/deprecation.py", line 141, in __acall__
    response = await sync_to_async(
               ^^^^^^^^^^^^^^^^^^^^
  File "/usr/local/lib/python3.11/site-packages/asgiref/sync.py", line 468, in __call__
    ret = await asyncio.shield(exec_coro)
          ^^^^^^^^^^^^^^^^^^^^^^^^^^^^^^^
  File "/usr/local/lib/python3.11/concurrent/futures/thread.py", line 58, in run
    result = self.fn(*self.args, **self.kwargs)
             ^^^^^^^^^^^^^^^^^^^^^^^^^^^^^^^^^^
  File "/usr/local/lib/python3.11/site-packages/asgiref/sync.py", line 522, in thread_handler
    return func(*args, **kwargs)
           ^^^^^^^^^^^^^^^^^^^^^
  File "/usr/local/lib/python3.11/site-packages/django/middleware/common.py", line 48, in process_request
    host = request.get_host()
           ^^^^^^^^^^^^^^^^^^
  File "/usr/local/lib/python3.11/site-packages/django/http/request.py", line 151, in get_host
    raise DisallowedHost(msg)
django.core.exceptions.DisallowedHost: Invalid HTTP_HOST header: '10.12.8.3'. You may need to add '10.12.8.3' to ALLOWED_HOSTS.
ERROR 2025-01-07 12:52:22,019 Invalid HTTP_HOST header: '10.12.8.3'. You may need to add '10.12.8.3' to ALLOWED_HOSTS.
Traceback (most recent call last):
  File "/usr/local/lib/python3.11/site-packages/asgiref/sync.py", line 518, in thread_handler
    raise exc_info[1]
  File "/usr/local/lib/python3.11/site-packages/django/core/handlers/exception.py", line 42, in inner
    response = await get_response(request)
               ^^^^^^^^^^^^^^^^^^^^^^^^^^^
  File "/usr/local/lib/python3.11/site-packages/django/utils/deprecation.py", line 141, in __acall__
    response = await sync_to_async(
               ^^^^^^^^^^^^^^^^^^^^
  File "/usr/local/lib/python3.11/site-packages/asgiref/sync.py", line 468, in __call__
    ret = await asyncio.shield(exec_coro)
          ^^^^^^^^^^^^^^^^^^^^^^^^^^^^^^^
  File "/usr/local/lib/python3.11/concurrent/futures/thread.py", line 58, in run
    result = self.fn(*self.args, **self.kwargs)
             ^^^^^^^^^^^^^^^^^^^^^^^^^^^^^^^^^^
  File "/usr/local/lib/python3.11/site-packages/asgiref/sync.py", line 522, in thread_handler
    return func(*args, **kwargs)
           ^^^^^^^^^^^^^^^^^^^^^
  File "/usr/local/lib/python3.11/site-packages/django/middleware/common.py", line 48, in process_request
    host = request.get_host()
           ^^^^^^^^^^^^^^^^^^
  File "/usr/local/lib/python3.11/site-packages/django/http/request.py", line 151, in get_host
    raise DisallowedHost(msg)
django.core.exceptions.DisallowedHost: Invalid HTTP_HOST header: '10.12.8.3'. You may need to add '10.12.8.3' to ALLOWED_HOSTS.
WARNING 2025-01-07 12:52:22,026 Bad Request: /favicon.ico
WARNING 2025-01-07 12:52:22,026 Bad Request: /favicon.ico
WARNING 2025-01-07 12:52:54,729 Forbidden: /accounts/users/me/get-myname/
WARNING 2025-01-07 12:52:54,729 Forbidden: /accounts/users/me/get-myname/
WARNING 2025-01-07 17:10:30,014 Forbidden: /accounts/users/me/get-myname/
WARNING 2025-01-07 17:10:30,014 Forbidden: /accounts/users/me/get-myname/
WARNING 2025-01-07 17:10:30,016 Not Found: /favicon.ico
WARNING 2025-01-07 17:10:30,016 Not Found: /favicon.ico
WARNING 2025-01-07 17:10:34,713 Forbidden (Origin checking failed - http://10.12.8.3:8080 does not match any trusted origins.): /admin/login/
WARNING 2025-01-07 17:10:34,713 Forbidden (Origin checking failed - http://10.12.8.3:8080 does not match any trusted origins.): /admin/login/
ERROR 2025-01-07 17:10:54,072 Internal Server Error: /admin/login/
Traceback (most recent call last):
  File "/usr/local/lib/python3.11/site-packages/django/db/backends/utils.py", line 105, in _execute
    return self.cursor.execute(sql, params)
           ^^^^^^^^^^^^^^^^^^^^^^^^^^^^^^^^
psycopg2.errors.UndefinedTable: relation "auth_user" does not exist
LINE 1: ...user"."is_active", "auth_user"."date_joined" FROM "auth_user...
                                                             ^


The above exception was the direct cause of the following exception:

Traceback (most recent call last):
  File "/usr/local/lib/python3.11/site-packages/asgiref/sync.py", line 518, in thread_handler
    raise exc_info[1]
  File "/usr/local/lib/python3.11/site-packages/django/core/handlers/exception.py", line 42, in inner
    response = await get_response(request)
               ^^^^^^^^^^^^^^^^^^^^^^^^^^^
  File "/usr/local/lib/python3.11/site-packages/asgiref/sync.py", line 518, in thread_handler
    raise exc_info[1]
  File "/usr/local/lib/python3.11/site-packages/django/core/handlers/base.py", line 253, in _get_response_async
    response = await wrapped_callback(
               ^^^^^^^^^^^^^^^^^^^^^^^
  File "/usr/local/lib/python3.11/site-packages/asgiref/sync.py", line 468, in __call__
    ret = await asyncio.shield(exec_coro)
          ^^^^^^^^^^^^^^^^^^^^^^^^^^^^^^^
  File "/usr/local/lib/python3.11/concurrent/futures/thread.py", line 58, in run
    result = self.fn(*self.args, **self.kwargs)
             ^^^^^^^^^^^^^^^^^^^^^^^^^^^^^^^^^^
  File "/usr/local/lib/python3.11/site-packages/asgiref/sync.py", line 522, in thread_handler
    return func(*args, **kwargs)
           ^^^^^^^^^^^^^^^^^^^^^
  File "/usr/local/lib/python3.11/site-packages/django/utils/decorators.py", line 48, in _wrapper
    return bound_method(*args, **kwargs)
           ^^^^^^^^^^^^^^^^^^^^^^^^^^^^^
  File "/usr/local/lib/python3.11/site-packages/django/views/decorators/cache.py", line 80, in _view_wrapper
    response = view_func(request, *args, **kwargs)
               ^^^^^^^^^^^^^^^^^^^^^^^^^^^^^^^^^^^
  File "/usr/local/lib/python3.11/site-packages/django/contrib/admin/sites.py", line 444, in login
    return LoginView.as_view(**defaults)(request)
           ^^^^^^^^^^^^^^^^^^^^^^^^^^^^^^^^^^^^^^
  File "/usr/local/lib/python3.11/site-packages/django/views/generic/base.py", line 104, in view
    return self.dispatch(request, *args, **kwargs)
           ^^^^^^^^^^^^^^^^^^^^^^^^^^^^^^^^^^^^^^^
  File "/usr/local/lib/python3.11/site-packages/django/utils/decorators.py", line 48, in _wrapper
    return bound_method(*args, **kwargs)
           ^^^^^^^^^^^^^^^^^^^^^^^^^^^^^
  File "/usr/local/lib/python3.11/site-packages/django/utils/decorators.py", line 48, in _wrapper
    return bound_method(*args, **kwargs)
           ^^^^^^^^^^^^^^^^^^^^^^^^^^^^^
  File "/usr/local/lib/python3.11/site-packages/django/views/decorators/debug.py", line 143, in sensitive_post_parameters_wrapper
    return view(request, *args, **kwargs)
           ^^^^^^^^^^^^^^^^^^^^^^^^^^^^^^
  File "/usr/local/lib/python3.11/site-packages/django/utils/decorators.py", line 48, in _wrapper
    return bound_method(*args, **kwargs)
           ^^^^^^^^^^^^^^^^^^^^^^^^^^^^^
  File "/usr/local/lib/python3.11/site-packages/django/utils/decorators.py", line 188, in _view_wrapper
    result = _process_exception(request, e)
             ^^^^^^^^^^^^^^^^^^^^^^^^^^^^^^
  File "/usr/local/lib/python3.11/site-packages/django/utils/decorators.py", line 186, in _view_wrapper
    response = view_func(request, *args, **kwargs)
               ^^^^^^^^^^^^^^^^^^^^^^^^^^^^^^^^^^^
  File "/usr/local/lib/python3.11/site-packages/django/utils/decorators.py", line 48, in _wrapper
    return bound_method(*args, **kwargs)
           ^^^^^^^^^^^^^^^^^^^^^^^^^^^^^
  File "/usr/local/lib/python3.11/site-packages/django/views/decorators/cache.py", line 80, in _view_wrapper
    response = view_func(request, *args, **kwargs)
               ^^^^^^^^^^^^^^^^^^^^^^^^^^^^^^^^^^^
  File "/usr/local/lib/python3.11/site-packages/django/contrib/auth/views.py", line 89, in dispatch
    return super().dispatch(request, *args, **kwargs)
           ^^^^^^^^^^^^^^^^^^^^^^^^^^^^^^^^^^^^^^^^^^
  File "/usr/local/lib/python3.11/site-packages/django/views/generic/base.py", line 143, in dispatch
    return handler(request, *args, **kwargs)
           ^^^^^^^^^^^^^^^^^^^^^^^^^^^^^^^^^
  File "/usr/local/lib/python3.11/site-packages/django/views/generic/edit.py", line 150, in post
    if form.is_valid():
       ^^^^^^^^^^^^^^^
  File "/usr/local/lib/python3.11/site-packages/django/forms/forms.py", line 197, in is_valid
    return self.is_bound and not self.errors
                                 ^^^^^^^^^^^
  File "/usr/local/lib/python3.11/site-packages/django/forms/forms.py", line 192, in errors
    self.full_clean()
  File "/usr/local/lib/python3.11/site-packages/django/forms/forms.py", line 326, in full_clean
    self._clean_form()
  File "/usr/local/lib/python3.11/site-packages/django/forms/forms.py", line 342, in _clean_form
    cleaned_data = self.clean()
                   ^^^^^^^^^^^^
  File "/usr/local/lib/python3.11/site-packages/django/contrib/auth/forms.py", line 356, in clean
    self.user_cache = authenticate(
                      ^^^^^^^^^^^^^
  File "/usr/local/lib/python3.11/site-packages/django/views/decorators/debug.py", line 75, in sensitive_variables_wrapper
    return func(*func_args, **func_kwargs)
           ^^^^^^^^^^^^^^^^^^^^^^^^^^^^^^^
  File "/usr/local/lib/python3.11/site-packages/django/contrib/auth/__init__.py", line 79, in authenticate
    user = backend.authenticate(request, **credentials)
           ^^^^^^^^^^^^^^^^^^^^^^^^^^^^^^^^^^^^^^^^^^^^
  File "/usr/local/lib/python3.11/site-packages/django/contrib/auth/backends.py", line 42, in authenticate
    user = UserModel._default_manager.get_by_natural_key(username)
           ^^^^^^^^^^^^^^^^^^^^^^^^^^^^^^^^^^^^^^^^^^^^^^^^^^^^^^^
  File "/usr/local/lib/python3.11/site-packages/django/contrib/auth/base_user.py", line 37, in get_by_natural_key
    return self.get(**{self.model.USERNAME_FIELD: username})
           ^^^^^^^^^^^^^^^^^^^^^^^^^^^^^^^^^^^^^^^^^^^^^^^^^
  File "/usr/local/lib/python3.11/site-packages/django/db/models/manager.py", line 87, in manager_method
    return getattr(self.get_queryset(), name)(*args, **kwargs)
           ^^^^^^^^^^^^^^^^^^^^^^^^^^^^^^^^^^^^^^^^^^^^^^^^^^^
  File "/usr/local/lib/python3.11/site-packages/django/db/models/query.py", line 645, in get
    num = len(clone)
          ^^^^^^^^^^
  File "/usr/local/lib/python3.11/site-packages/django/db/models/query.py", line 382, in __len__
    self._fetch_all()
  File "/usr/local/lib/python3.11/site-packages/django/db/models/query.py", line 1928, in _fetch_all
    self._result_cache = list(self._iterable_class(self))
                         ^^^^^^^^^^^^^^^^^^^^^^^^^^^^^^^^
  File "/usr/local/lib/python3.11/site-packages/django/db/models/query.py", line 91, in __iter__
    results = compiler.execute_sql(
              ^^^^^^^^^^^^^^^^^^^^^
  File "/usr/local/lib/python3.11/site-packages/django/db/models/sql/compiler.py", line 1574, in execute_sql
    cursor.execute(sql, params)
  File "/usr/local/lib/python3.11/site-packages/django/db/backends/utils.py", line 122, in execute
    return super().execute(sql, params)
           ^^^^^^^^^^^^^^^^^^^^^^^^^^^^
  File "/usr/local/lib/python3.11/site-packages/django/db/backends/utils.py", line 79, in execute
    return self._execute_with_wrappers(
           ^^^^^^^^^^^^^^^^^^^^^^^^^^^^
  File "/usr/local/lib/python3.11/site-packages/django/db/backends/utils.py", line 92, in _execute_with_wrappers
    return executor(sql, params, many, context)
           ^^^^^^^^^^^^^^^^^^^^^^^^^^^^^^^^^^^^
  File "/usr/local/lib/python3.11/site-packages/django/db/backends/utils.py", line 100, in _execute
    with self.db.wrap_database_errors:
  File "/usr/local/lib/python3.11/site-packages/django/db/utils.py", line 91, in __exit__
    raise dj_exc_value.with_traceback(traceback) from exc_value
  File "/usr/local/lib/python3.11/site-packages/django/db/backends/utils.py", line 105, in _execute
    return self.cursor.execute(sql, params)
           ^^^^^^^^^^^^^^^^^^^^^^^^^^^^^^^^
django.db.utils.ProgrammingError: relation "auth_user" does not exist
LINE 1: ...user"."is_active", "auth_user"."date_joined" FROM "auth_user...
                                                             ^

ERROR 2025-01-07 17:10:54,072 Internal Server Error: /admin/login/
Traceback (most recent call last):
  File "/usr/local/lib/python3.11/site-packages/django/db/backends/utils.py", line 105, in _execute
    return self.cursor.execute(sql, params)
           ^^^^^^^^^^^^^^^^^^^^^^^^^^^^^^^^
psycopg2.errors.UndefinedTable: relation "auth_user" does not exist
LINE 1: ...user"."is_active", "auth_user"."date_joined" FROM "auth_user...
                                                             ^


The above exception was the direct cause of the following exception:

Traceback (most recent call last):
  File "/usr/local/lib/python3.11/site-packages/asgiref/sync.py", line 518, in thread_handler
    raise exc_info[1]
  File "/usr/local/lib/python3.11/site-packages/django/core/handlers/exception.py", line 42, in inner
    response = await get_response(request)
               ^^^^^^^^^^^^^^^^^^^^^^^^^^^
  File "/usr/local/lib/python3.11/site-packages/asgiref/sync.py", line 518, in thread_handler
    raise exc_info[1]
  File "/usr/local/lib/python3.11/site-packages/django/core/handlers/base.py", line 253, in _get_response_async
    response = await wrapped_callback(
               ^^^^^^^^^^^^^^^^^^^^^^^
  File "/usr/local/lib/python3.11/site-packages/asgiref/sync.py", line 468, in __call__
    ret = await asyncio.shield(exec_coro)
          ^^^^^^^^^^^^^^^^^^^^^^^^^^^^^^^
  File "/usr/local/lib/python3.11/concurrent/futures/thread.py", line 58, in run
    result = self.fn(*self.args, **self.kwargs)
             ^^^^^^^^^^^^^^^^^^^^^^^^^^^^^^^^^^
  File "/usr/local/lib/python3.11/site-packages/asgiref/sync.py", line 522, in thread_handler
    return func(*args, **kwargs)
           ^^^^^^^^^^^^^^^^^^^^^
  File "/usr/local/lib/python3.11/site-packages/django/utils/decorators.py", line 48, in _wrapper
    return bound_method(*args, **kwargs)
           ^^^^^^^^^^^^^^^^^^^^^^^^^^^^^
  File "/usr/local/lib/python3.11/site-packages/django/views/decorators/cache.py", line 80, in _view_wrapper
    response = view_func(request, *args, **kwargs)
               ^^^^^^^^^^^^^^^^^^^^^^^^^^^^^^^^^^^
  File "/usr/local/lib/python3.11/site-packages/django/contrib/admin/sites.py", line 444, in login
    return LoginView.as_view(**defaults)(request)
           ^^^^^^^^^^^^^^^^^^^^^^^^^^^^^^^^^^^^^^
  File "/usr/local/lib/python3.11/site-packages/django/views/generic/base.py", line 104, in view
    return self.dispatch(request, *args, **kwargs)
           ^^^^^^^^^^^^^^^^^^^^^^^^^^^^^^^^^^^^^^^
  File "/usr/local/lib/python3.11/site-packages/django/utils/decorators.py", line 48, in _wrapper
    return bound_method(*args, **kwargs)
           ^^^^^^^^^^^^^^^^^^^^^^^^^^^^^
  File "/usr/local/lib/python3.11/site-packages/django/utils/decorators.py", line 48, in _wrapper
    return bound_method(*args, **kwargs)
           ^^^^^^^^^^^^^^^^^^^^^^^^^^^^^
  File "/usr/local/lib/python3.11/site-packages/django/views/decorators/debug.py", line 143, in sensitive_post_parameters_wrapper
    return view(request, *args, **kwargs)
           ^^^^^^^^^^^^^^^^^^^^^^^^^^^^^^
  File "/usr/local/lib/python3.11/site-packages/django/utils/decorators.py", line 48, in _wrapper
    return bound_method(*args, **kwargs)
           ^^^^^^^^^^^^^^^^^^^^^^^^^^^^^
  File "/usr/local/lib/python3.11/site-packages/django/utils/decorators.py", line 188, in _view_wrapper
    result = _process_exception(request, e)
             ^^^^^^^^^^^^^^^^^^^^^^^^^^^^^^
  File "/usr/local/lib/python3.11/site-packages/django/utils/decorators.py", line 186, in _view_wrapper
    response = view_func(request, *args, **kwargs)
               ^^^^^^^^^^^^^^^^^^^^^^^^^^^^^^^^^^^
  File "/usr/local/lib/python3.11/site-packages/django/utils/decorators.py", line 48, in _wrapper
    return bound_method(*args, **kwargs)
           ^^^^^^^^^^^^^^^^^^^^^^^^^^^^^
  File "/usr/local/lib/python3.11/site-packages/django/views/decorators/cache.py", line 80, in _view_wrapper
    response = view_func(request, *args, **kwargs)
               ^^^^^^^^^^^^^^^^^^^^^^^^^^^^^^^^^^^
  File "/usr/local/lib/python3.11/site-packages/django/contrib/auth/views.py", line 89, in dispatch
    return super().dispatch(request, *args, **kwargs)
           ^^^^^^^^^^^^^^^^^^^^^^^^^^^^^^^^^^^^^^^^^^
  File "/usr/local/lib/python3.11/site-packages/django/views/generic/base.py", line 143, in dispatch
    return handler(request, *args, **kwargs)
           ^^^^^^^^^^^^^^^^^^^^^^^^^^^^^^^^^
  File "/usr/local/lib/python3.11/site-packages/django/views/generic/edit.py", line 150, in post
    if form.is_valid():
       ^^^^^^^^^^^^^^^
  File "/usr/local/lib/python3.11/site-packages/django/forms/forms.py", line 197, in is_valid
    return self.is_bound and not self.errors
                                 ^^^^^^^^^^^
  File "/usr/local/lib/python3.11/site-packages/django/forms/forms.py", line 192, in errors
    self.full_clean()
  File "/usr/local/lib/python3.11/site-packages/django/forms/forms.py", line 326, in full_clean
    self._clean_form()
  File "/usr/local/lib/python3.11/site-packages/django/forms/forms.py", line 342, in _clean_form
    cleaned_data = self.clean()
                   ^^^^^^^^^^^^
  File "/usr/local/lib/python3.11/site-packages/django/contrib/auth/forms.py", line 356, in clean
    self.user_cache = authenticate(
                      ^^^^^^^^^^^^^
  File "/usr/local/lib/python3.11/site-packages/django/views/decorators/debug.py", line 75, in sensitive_variables_wrapper
    return func(*func_args, **func_kwargs)
           ^^^^^^^^^^^^^^^^^^^^^^^^^^^^^^^
  File "/usr/local/lib/python3.11/site-packages/django/contrib/auth/__init__.py", line 79, in authenticate
    user = backend.authenticate(request, **credentials)
           ^^^^^^^^^^^^^^^^^^^^^^^^^^^^^^^^^^^^^^^^^^^^
  File "/usr/local/lib/python3.11/site-packages/django/contrib/auth/backends.py", line 42, in authenticate
    user = UserModel._default_manager.get_by_natural_key(username)
           ^^^^^^^^^^^^^^^^^^^^^^^^^^^^^^^^^^^^^^^^^^^^^^^^^^^^^^^
  File "/usr/local/lib/python3.11/site-packages/django/contrib/auth/base_user.py", line 37, in get_by_natural_key
    return self.get(**{self.model.USERNAME_FIELD: username})
           ^^^^^^^^^^^^^^^^^^^^^^^^^^^^^^^^^^^^^^^^^^^^^^^^^
  File "/usr/local/lib/python3.11/site-packages/django/db/models/manager.py", line 87, in manager_method
    return getattr(self.get_queryset(), name)(*args, **kwargs)
           ^^^^^^^^^^^^^^^^^^^^^^^^^^^^^^^^^^^^^^^^^^^^^^^^^^^
  File "/usr/local/lib/python3.11/site-packages/django/db/models/query.py", line 645, in get
    num = len(clone)
          ^^^^^^^^^^
  File "/usr/local/lib/python3.11/site-packages/django/db/models/query.py", line 382, in __len__
    self._fetch_all()
  File "/usr/local/lib/python3.11/site-packages/django/db/models/query.py", line 1928, in _fetch_all
    self._result_cache = list(self._iterable_class(self))
                         ^^^^^^^^^^^^^^^^^^^^^^^^^^^^^^^^
  File "/usr/local/lib/python3.11/site-packages/django/db/models/query.py", line 91, in __iter__
    results = compiler.execute_sql(
              ^^^^^^^^^^^^^^^^^^^^^
  File "/usr/local/lib/python3.11/site-packages/django/db/models/sql/compiler.py", line 1574, in execute_sql
    cursor.execute(sql, params)
  File "/usr/local/lib/python3.11/site-packages/django/db/backends/utils.py", line 122, in execute
    return super().execute(sql, params)
           ^^^^^^^^^^^^^^^^^^^^^^^^^^^^
  File "/usr/local/lib/python3.11/site-packages/django/db/backends/utils.py", line 79, in execute
    return self._execute_with_wrappers(
           ^^^^^^^^^^^^^^^^^^^^^^^^^^^^
  File "/usr/local/lib/python3.11/site-packages/django/db/backends/utils.py", line 92, in _execute_with_wrappers
    return executor(sql, params, many, context)
           ^^^^^^^^^^^^^^^^^^^^^^^^^^^^^^^^^^^^
  File "/usr/local/lib/python3.11/site-packages/django/db/backends/utils.py", line 100, in _execute
    with self.db.wrap_database_errors:
  File "/usr/local/lib/python3.11/site-packages/django/db/utils.py", line 91, in __exit__
    raise dj_exc_value.with_traceback(traceback) from exc_value
  File "/usr/local/lib/python3.11/site-packages/django/db/backends/utils.py", line 105, in _execute
    return self.cursor.execute(sql, params)
           ^^^^^^^^^^^^^^^^^^^^^^^^^^^^^^^^
django.db.utils.ProgrammingError: relation "auth_user" does not exist
LINE 1: ...user"."is_active", "auth_user"."date_joined" FROM "auth_user...
                                                             ^

WARNING 2025-01-07 17:10:56,970 Forbidden: /accounts/users/me/get-myname/
WARNING 2025-01-07 17:10:56,970 Forbidden: /accounts/users/me/get-myname/
ERROR 2025-01-07 17:11:01,040 Internal Server Error: /admin/login/
Traceback (most recent call last):
  File "/usr/local/lib/python3.11/site-packages/django/db/backends/utils.py", line 105, in _execute
    return self.cursor.execute(sql, params)
           ^^^^^^^^^^^^^^^^^^^^^^^^^^^^^^^^
psycopg2.errors.UndefinedTable: relation "auth_user" does not exist
LINE 1: ...user"."is_active", "auth_user"."date_joined" FROM "auth_user...
                                                             ^


The above exception was the direct cause of the following exception:

Traceback (most recent call last):
  File "/usr/local/lib/python3.11/site-packages/asgiref/sync.py", line 518, in thread_handler
    raise exc_info[1]
  File "/usr/local/lib/python3.11/site-packages/django/core/handlers/exception.py", line 42, in inner
    response = await get_response(request)
               ^^^^^^^^^^^^^^^^^^^^^^^^^^^
  File "/usr/local/lib/python3.11/site-packages/asgiref/sync.py", line 518, in thread_handler
    raise exc_info[1]
  File "/usr/local/lib/python3.11/site-packages/django/core/handlers/base.py", line 253, in _get_response_async
    response = await wrapped_callback(
               ^^^^^^^^^^^^^^^^^^^^^^^
  File "/usr/local/lib/python3.11/site-packages/asgiref/sync.py", line 468, in __call__
    ret = await asyncio.shield(exec_coro)
          ^^^^^^^^^^^^^^^^^^^^^^^^^^^^^^^
  File "/usr/local/lib/python3.11/concurrent/futures/thread.py", line 58, in run
    result = self.fn(*self.args, **self.kwargs)
             ^^^^^^^^^^^^^^^^^^^^^^^^^^^^^^^^^^
  File "/usr/local/lib/python3.11/site-packages/asgiref/sync.py", line 522, in thread_handler
    return func(*args, **kwargs)
           ^^^^^^^^^^^^^^^^^^^^^
  File "/usr/local/lib/python3.11/site-packages/django/utils/decorators.py", line 48, in _wrapper
    return bound_method(*args, **kwargs)
           ^^^^^^^^^^^^^^^^^^^^^^^^^^^^^
  File "/usr/local/lib/python3.11/site-packages/django/views/decorators/cache.py", line 80, in _view_wrapper
    response = view_func(request, *args, **kwargs)
               ^^^^^^^^^^^^^^^^^^^^^^^^^^^^^^^^^^^
  File "/usr/local/lib/python3.11/site-packages/django/contrib/admin/sites.py", line 444, in login
    return LoginView.as_view(**defaults)(request)
           ^^^^^^^^^^^^^^^^^^^^^^^^^^^^^^^^^^^^^^
  File "/usr/local/lib/python3.11/site-packages/django/views/generic/base.py", line 104, in view
    return self.dispatch(request, *args, **kwargs)
           ^^^^^^^^^^^^^^^^^^^^^^^^^^^^^^^^^^^^^^^
  File "/usr/local/lib/python3.11/site-packages/django/utils/decorators.py", line 48, in _wrapper
    return bound_method(*args, **kwargs)
           ^^^^^^^^^^^^^^^^^^^^^^^^^^^^^
  File "/usr/local/lib/python3.11/site-packages/django/utils/decorators.py", line 48, in _wrapper
    return bound_method(*args, **kwargs)
           ^^^^^^^^^^^^^^^^^^^^^^^^^^^^^
  File "/usr/local/lib/python3.11/site-packages/django/views/decorators/debug.py", line 143, in sensitive_post_parameters_wrapper
    return view(request, *args, **kwargs)
           ^^^^^^^^^^^^^^^^^^^^^^^^^^^^^^
  File "/usr/local/lib/python3.11/site-packages/django/utils/decorators.py", line 48, in _wrapper
    return bound_method(*args, **kwargs)
           ^^^^^^^^^^^^^^^^^^^^^^^^^^^^^
  File "/usr/local/lib/python3.11/site-packages/django/utils/decorators.py", line 188, in _view_wrapper
    result = _process_exception(request, e)
             ^^^^^^^^^^^^^^^^^^^^^^^^^^^^^^
  File "/usr/local/lib/python3.11/site-packages/django/utils/decorators.py", line 186, in _view_wrapper
    response = view_func(request, *args, **kwargs)
               ^^^^^^^^^^^^^^^^^^^^^^^^^^^^^^^^^^^
  File "/usr/local/lib/python3.11/site-packages/django/utils/decorators.py", line 48, in _wrapper
    return bound_method(*args, **kwargs)
           ^^^^^^^^^^^^^^^^^^^^^^^^^^^^^
  File "/usr/local/lib/python3.11/site-packages/django/views/decorators/cache.py", line 80, in _view_wrapper
    response = view_func(request, *args, **kwargs)
               ^^^^^^^^^^^^^^^^^^^^^^^^^^^^^^^^^^^
  File "/usr/local/lib/python3.11/site-packages/django/contrib/auth/views.py", line 89, in dispatch
    return super().dispatch(request, *args, **kwargs)
           ^^^^^^^^^^^^^^^^^^^^^^^^^^^^^^^^^^^^^^^^^^
  File "/usr/local/lib/python3.11/site-packages/django/views/generic/base.py", line 143, in dispatch
    return handler(request, *args, **kwargs)
           ^^^^^^^^^^^^^^^^^^^^^^^^^^^^^^^^^
  File "/usr/local/lib/python3.11/site-packages/django/views/generic/edit.py", line 150, in post
    if form.is_valid():
       ^^^^^^^^^^^^^^^
  File "/usr/local/lib/python3.11/site-packages/django/forms/forms.py", line 197, in is_valid
    return self.is_bound and not self.errors
                                 ^^^^^^^^^^^
  File "/usr/local/lib/python3.11/site-packages/django/forms/forms.py", line 192, in errors
    self.full_clean()
  File "/usr/local/lib/python3.11/site-packages/django/forms/forms.py", line 326, in full_clean
    self._clean_form()
  File "/usr/local/lib/python3.11/site-packages/django/forms/forms.py", line 342, in _clean_form
    cleaned_data = self.clean()
                   ^^^^^^^^^^^^
  File "/usr/local/lib/python3.11/site-packages/django/contrib/auth/forms.py", line 356, in clean
    self.user_cache = authenticate(
                      ^^^^^^^^^^^^^
  File "/usr/local/lib/python3.11/site-packages/django/views/decorators/debug.py", line 75, in sensitive_variables_wrapper
    return func(*func_args, **func_kwargs)
           ^^^^^^^^^^^^^^^^^^^^^^^^^^^^^^^
  File "/usr/local/lib/python3.11/site-packages/django/contrib/auth/__init__.py", line 79, in authenticate
    user = backend.authenticate(request, **credentials)
           ^^^^^^^^^^^^^^^^^^^^^^^^^^^^^^^^^^^^^^^^^^^^
  File "/usr/local/lib/python3.11/site-packages/django/contrib/auth/backends.py", line 42, in authenticate
    user = UserModel._default_manager.get_by_natural_key(username)
           ^^^^^^^^^^^^^^^^^^^^^^^^^^^^^^^^^^^^^^^^^^^^^^^^^^^^^^^
  File "/usr/local/lib/python3.11/site-packages/django/contrib/auth/base_user.py", line 37, in get_by_natural_key
    return self.get(**{self.model.USERNAME_FIELD: username})
           ^^^^^^^^^^^^^^^^^^^^^^^^^^^^^^^^^^^^^^^^^^^^^^^^^
  File "/usr/local/lib/python3.11/site-packages/django/db/models/manager.py", line 87, in manager_method
    return getattr(self.get_queryset(), name)(*args, **kwargs)
           ^^^^^^^^^^^^^^^^^^^^^^^^^^^^^^^^^^^^^^^^^^^^^^^^^^^
  File "/usr/local/lib/python3.11/site-packages/django/db/models/query.py", line 645, in get
    num = len(clone)
          ^^^^^^^^^^
  File "/usr/local/lib/python3.11/site-packages/django/db/models/query.py", line 382, in __len__
    self._fetch_all()
  File "/usr/local/lib/python3.11/site-packages/django/db/models/query.py", line 1928, in _fetch_all
    self._result_cache = list(self._iterable_class(self))
                         ^^^^^^^^^^^^^^^^^^^^^^^^^^^^^^^^
  File "/usr/local/lib/python3.11/site-packages/django/db/models/query.py", line 91, in __iter__
    results = compiler.execute_sql(
              ^^^^^^^^^^^^^^^^^^^^^
  File "/usr/local/lib/python3.11/site-packages/django/db/models/sql/compiler.py", line 1574, in execute_sql
    cursor.execute(sql, params)
  File "/usr/local/lib/python3.11/site-packages/django/db/backends/utils.py", line 122, in execute
    return super().execute(sql, params)
           ^^^^^^^^^^^^^^^^^^^^^^^^^^^^
  File "/usr/local/lib/python3.11/site-packages/django/db/backends/utils.py", line 79, in execute
    return self._execute_with_wrappers(
           ^^^^^^^^^^^^^^^^^^^^^^^^^^^^
  File "/usr/local/lib/python3.11/site-packages/django/db/backends/utils.py", line 92, in _execute_with_wrappers
    return executor(sql, params, many, context)
           ^^^^^^^^^^^^^^^^^^^^^^^^^^^^^^^^^^^^
  File "/usr/local/lib/python3.11/site-packages/django/db/backends/utils.py", line 100, in _execute
    with self.db.wrap_database_errors:
  File "/usr/local/lib/python3.11/site-packages/django/db/utils.py", line 91, in __exit__
    raise dj_exc_value.with_traceback(traceback) from exc_value
  File "/usr/local/lib/python3.11/site-packages/django/db/backends/utils.py", line 105, in _execute
    return self.cursor.execute(sql, params)
           ^^^^^^^^^^^^^^^^^^^^^^^^^^^^^^^^
django.db.utils.ProgrammingError: relation "auth_user" does not exist
LINE 1: ...user"."is_active", "auth_user"."date_joined" FROM "auth_user...
                                                             ^

ERROR 2025-01-07 17:11:01,040 Internal Server Error: /admin/login/
Traceback (most recent call last):
  File "/usr/local/lib/python3.11/site-packages/django/db/backends/utils.py", line 105, in _execute
    return self.cursor.execute(sql, params)
           ^^^^^^^^^^^^^^^^^^^^^^^^^^^^^^^^
psycopg2.errors.UndefinedTable: relation "auth_user" does not exist
LINE 1: ...user"."is_active", "auth_user"."date_joined" FROM "auth_user...
                                                             ^


The above exception was the direct cause of the following exception:

Traceback (most recent call last):
  File "/usr/local/lib/python3.11/site-packages/asgiref/sync.py", line 518, in thread_handler
    raise exc_info[1]
  File "/usr/local/lib/python3.11/site-packages/django/core/handlers/exception.py", line 42, in inner
    response = await get_response(request)
               ^^^^^^^^^^^^^^^^^^^^^^^^^^^
  File "/usr/local/lib/python3.11/site-packages/asgiref/sync.py", line 518, in thread_handler
    raise exc_info[1]
  File "/usr/local/lib/python3.11/site-packages/django/core/handlers/base.py", line 253, in _get_response_async
    response = await wrapped_callback(
               ^^^^^^^^^^^^^^^^^^^^^^^
  File "/usr/local/lib/python3.11/site-packages/asgiref/sync.py", line 468, in __call__
    ret = await asyncio.shield(exec_coro)
          ^^^^^^^^^^^^^^^^^^^^^^^^^^^^^^^
  File "/usr/local/lib/python3.11/concurrent/futures/thread.py", line 58, in run
    result = self.fn(*self.args, **self.kwargs)
             ^^^^^^^^^^^^^^^^^^^^^^^^^^^^^^^^^^
  File "/usr/local/lib/python3.11/site-packages/asgiref/sync.py", line 522, in thread_handler
    return func(*args, **kwargs)
           ^^^^^^^^^^^^^^^^^^^^^
  File "/usr/local/lib/python3.11/site-packages/django/utils/decorators.py", line 48, in _wrapper
    return bound_method(*args, **kwargs)
           ^^^^^^^^^^^^^^^^^^^^^^^^^^^^^
  File "/usr/local/lib/python3.11/site-packages/django/views/decorators/cache.py", line 80, in _view_wrapper
    response = view_func(request, *args, **kwargs)
               ^^^^^^^^^^^^^^^^^^^^^^^^^^^^^^^^^^^
  File "/usr/local/lib/python3.11/site-packages/django/contrib/admin/sites.py", line 444, in login
    return LoginView.as_view(**defaults)(request)
           ^^^^^^^^^^^^^^^^^^^^^^^^^^^^^^^^^^^^^^
  File "/usr/local/lib/python3.11/site-packages/django/views/generic/base.py", line 104, in view
    return self.dispatch(request, *args, **kwargs)
           ^^^^^^^^^^^^^^^^^^^^^^^^^^^^^^^^^^^^^^^
  File "/usr/local/lib/python3.11/site-packages/django/utils/decorators.py", line 48, in _wrapper
    return bound_method(*args, **kwargs)
           ^^^^^^^^^^^^^^^^^^^^^^^^^^^^^
  File "/usr/local/lib/python3.11/site-packages/django/utils/decorators.py", line 48, in _wrapper
    return bound_method(*args, **kwargs)
           ^^^^^^^^^^^^^^^^^^^^^^^^^^^^^
  File "/usr/local/lib/python3.11/site-packages/django/views/decorators/debug.py", line 143, in sensitive_post_parameters_wrapper
    return view(request, *args, **kwargs)
           ^^^^^^^^^^^^^^^^^^^^^^^^^^^^^^
  File "/usr/local/lib/python3.11/site-packages/django/utils/decorators.py", line 48, in _wrapper
    return bound_method(*args, **kwargs)
           ^^^^^^^^^^^^^^^^^^^^^^^^^^^^^
  File "/usr/local/lib/python3.11/site-packages/django/utils/decorators.py", line 188, in _view_wrapper
    result = _process_exception(request, e)
             ^^^^^^^^^^^^^^^^^^^^^^^^^^^^^^
  File "/usr/local/lib/python3.11/site-packages/django/utils/decorators.py", line 186, in _view_wrapper
    response = view_func(request, *args, **kwargs)
               ^^^^^^^^^^^^^^^^^^^^^^^^^^^^^^^^^^^
  File "/usr/local/lib/python3.11/site-packages/django/utils/decorators.py", line 48, in _wrapper
    return bound_method(*args, **kwargs)
           ^^^^^^^^^^^^^^^^^^^^^^^^^^^^^
  File "/usr/local/lib/python3.11/site-packages/django/views/decorators/cache.py", line 80, in _view_wrapper
    response = view_func(request, *args, **kwargs)
               ^^^^^^^^^^^^^^^^^^^^^^^^^^^^^^^^^^^
  File "/usr/local/lib/python3.11/site-packages/django/contrib/auth/views.py", line 89, in dispatch
    return super().dispatch(request, *args, **kwargs)
           ^^^^^^^^^^^^^^^^^^^^^^^^^^^^^^^^^^^^^^^^^^
  File "/usr/local/lib/python3.11/site-packages/django/views/generic/base.py", line 143, in dispatch
    return handler(request, *args, **kwargs)
           ^^^^^^^^^^^^^^^^^^^^^^^^^^^^^^^^^
  File "/usr/local/lib/python3.11/site-packages/django/views/generic/edit.py", line 150, in post
    if form.is_valid():
       ^^^^^^^^^^^^^^^
  File "/usr/local/lib/python3.11/site-packages/django/forms/forms.py", line 197, in is_valid
    return self.is_bound and not self.errors
                                 ^^^^^^^^^^^
  File "/usr/local/lib/python3.11/site-packages/django/forms/forms.py", line 192, in errors
    self.full_clean()
  File "/usr/local/lib/python3.11/site-packages/django/forms/forms.py", line 326, in full_clean
    self._clean_form()
  File "/usr/local/lib/python3.11/site-packages/django/forms/forms.py", line 342, in _clean_form
    cleaned_data = self.clean()
                   ^^^^^^^^^^^^
  File "/usr/local/lib/python3.11/site-packages/django/contrib/auth/forms.py", line 356, in clean
    self.user_cache = authenticate(
                      ^^^^^^^^^^^^^
  File "/usr/local/lib/python3.11/site-packages/django/views/decorators/debug.py", line 75, in sensitive_variables_wrapper
    return func(*func_args, **func_kwargs)
           ^^^^^^^^^^^^^^^^^^^^^^^^^^^^^^^
  File "/usr/local/lib/python3.11/site-packages/django/contrib/auth/__init__.py", line 79, in authenticate
    user = backend.authenticate(request, **credentials)
           ^^^^^^^^^^^^^^^^^^^^^^^^^^^^^^^^^^^^^^^^^^^^
  File "/usr/local/lib/python3.11/site-packages/django/contrib/auth/backends.py", line 42, in authenticate
    user = UserModel._default_manager.get_by_natural_key(username)
           ^^^^^^^^^^^^^^^^^^^^^^^^^^^^^^^^^^^^^^^^^^^^^^^^^^^^^^^
  File "/usr/local/lib/python3.11/site-packages/django/contrib/auth/base_user.py", line 37, in get_by_natural_key
    return self.get(**{self.model.USERNAME_FIELD: username})
           ^^^^^^^^^^^^^^^^^^^^^^^^^^^^^^^^^^^^^^^^^^^^^^^^^
  File "/usr/local/lib/python3.11/site-packages/django/db/models/manager.py", line 87, in manager_method
    return getattr(self.get_queryset(), name)(*args, **kwargs)
           ^^^^^^^^^^^^^^^^^^^^^^^^^^^^^^^^^^^^^^^^^^^^^^^^^^^
  File "/usr/local/lib/python3.11/site-packages/django/db/models/query.py", line 645, in get
    num = len(clone)
          ^^^^^^^^^^
  File "/usr/local/lib/python3.11/site-packages/django/db/models/query.py", line 382, in __len__
    self._fetch_all()
  File "/usr/local/lib/python3.11/site-packages/django/db/models/query.py", line 1928, in _fetch_all
    self._result_cache = list(self._iterable_class(self))
                         ^^^^^^^^^^^^^^^^^^^^^^^^^^^^^^^^
  File "/usr/local/lib/python3.11/site-packages/django/db/models/query.py", line 91, in __iter__
    results = compiler.execute_sql(
              ^^^^^^^^^^^^^^^^^^^^^
  File "/usr/local/lib/python3.11/site-packages/django/db/models/sql/compiler.py", line 1574, in execute_sql
    cursor.execute(sql, params)
  File "/usr/local/lib/python3.11/site-packages/django/db/backends/utils.py", line 122, in execute
    return super().execute(sql, params)
           ^^^^^^^^^^^^^^^^^^^^^^^^^^^^
  File "/usr/local/lib/python3.11/site-packages/django/db/backends/utils.py", line 79, in execute
    return self._execute_with_wrappers(
           ^^^^^^^^^^^^^^^^^^^^^^^^^^^^
  File "/usr/local/lib/python3.11/site-packages/django/db/backends/utils.py", line 92, in _execute_with_wrappers
    return executor(sql, params, many, context)
           ^^^^^^^^^^^^^^^^^^^^^^^^^^^^^^^^^^^^
  File "/usr/local/lib/python3.11/site-packages/django/db/backends/utils.py", line 100, in _execute
    with self.db.wrap_database_errors:
  File "/usr/local/lib/python3.11/site-packages/django/db/utils.py", line 91, in __exit__
    raise dj_exc_value.with_traceback(traceback) from exc_value
  File "/usr/local/lib/python3.11/site-packages/django/db/backends/utils.py", line 105, in _execute
    return self.cursor.execute(sql, params)
           ^^^^^^^^^^^^^^^^^^^^^^^^^^^^^^^^
django.db.utils.ProgrammingError: relation "auth_user" does not exist
LINE 1: ...user"."is_active", "auth_user"."date_joined" FROM "auth_user...
                                                             ^

WARNING 2025-01-07 17:16:42,659 Forbidden: /accounts/users/me/get-myname/
WARNING 2025-01-07 17:16:42,659 Forbidden: /accounts/users/me/get-myname/
WARNING 2025-01-07 17:17:00,422 Forbidden: /accounts/users/me/get-myname/
WARNING 2025-01-07 17:17:00,422 Forbidden: /accounts/users/me/get-myname/
WARNING 2025-01-07 17:17:00,435 Not Found: /favicon.ico
WARNING 2025-01-07 17:17:00,435 Not Found: /favicon.ico
WARNING 2025-01-07 17:17:49,795 Forbidden: /accounts/users/me/get-myname/
WARNING 2025-01-07 17:17:49,795 Forbidden: /accounts/users/me/get-myname/
WARNING 2025-01-07 17:19:06,746 Forbidden: /accounts/users/me/get-myname/
WARNING 2025-01-07 17:19:06,746 Forbidden: /accounts/users/me/get-myname/
WARNING 2025-01-07 17:19:06,756 Not Found: /favicon.ico
WARNING 2025-01-07 17:19:06,756 Not Found: /favicon.ico
WARNING 2025-01-07 17:20:24,922 Forbidden: /accounts/users/me/get-myname/
WARNING 2025-01-07 17:20:24,922 Forbidden: /accounts/users/me/get-myname/
WARNING 2025-01-07 17:20:24,930 Not Found: /favicon.ico
WARNING 2025-01-07 17:20:24,930 Not Found: /favicon.ico
WARNING 2025-01-07 18:37:52,747 Forbidden: /accounts/users/me/get-myname/
WARNING 2025-01-07 18:37:52,747 Forbidden: /accounts/users/me/get-myname/
WARNING 2025-01-07 18:37:52,766 Not Found: /favicon.ico
WARNING 2025-01-07 18:37:52,766 Not Found: /favicon.ico
ERROR 2025-01-07 18:49:15,608 Internal Server Error: /admin/auth/user/
Traceback (most recent call last):
  File "/usr/local/lib/python3.11/site-packages/django/db/models/options.py", line 676, in get_field
    return self.fields_map[field_name]
           ~~~~~~~~~~~~~~~^^^^^^^^^^^^
KeyError: <function get_is_online at 0x757df215dda0>

During handling of the above exception, another exception occurred:

Traceback (most recent call last):
  File "/usr/local/lib/python3.11/site-packages/django/contrib/admin/utils.py", line 290, in lookup_field
    f = _get_non_gfk_field(opts, name)
        ^^^^^^^^^^^^^^^^^^^^^^^^^^^^^^
  File "/usr/local/lib/python3.11/site-packages/django/contrib/admin/utils.py", line 330, in _get_non_gfk_field
    field = opts.get_field(name)
            ^^^^^^^^^^^^^^^^^^^^
  File "/usr/local/lib/python3.11/site-packages/django/db/models/options.py", line 678, in get_field
    raise FieldDoesNotExist(
django.core.exceptions.FieldDoesNotExist: User has no field named '<function get_is_online at 0x757df215dda0>'

During handling of the above exception, another exception occurred:

Traceback (most recent call last):
  File "/usr/local/lib/python3.11/site-packages/django/db/models/fields/related_descriptors.py", line 512, in __get__
    rel_obj = self.related.get_cached_value(instance)
              ^^^^^^^^^^^^^^^^^^^^^^^^^^^^^^^^^^^^^^^
  File "/usr/local/lib/python3.11/site-packages/django/db/models/fields/mixins.py", line 37, in get_cached_value
    return instance._state.fields_cache[self.cache_name]
           ~~~~~~~~~~~~~~~~~~~~~~~~~~~~^^^^^^^^^^^^^^^^^
KeyError: 'profile'

During handling of the above exception, another exception occurred:

Traceback (most recent call last):
  File "/usr/local/lib/python3.11/site-packages/django/db/backends/utils.py", line 105, in _execute
    return self.cursor.execute(sql, params)
           ^^^^^^^^^^^^^^^^^^^^^^^^^^^^^^^^
psycopg2.errors.UndefinedColumn: column accounts_profile.win_count does not exist
LINE 1: ...profile"."is_online", "accounts_profile"."image", "accounts_...
                                                             ^


The above exception was the direct cause of the following exception:

Traceback (most recent call last):
  File "/usr/local/lib/python3.11/site-packages/asgiref/sync.py", line 518, in thread_handler
    raise exc_info[1]
  File "/usr/local/lib/python3.11/site-packages/django/core/handlers/exception.py", line 42, in inner
    response = await get_response(request)
               ^^^^^^^^^^^^^^^^^^^^^^^^^^^
  File "/usr/local/lib/python3.11/site-packages/asgiref/sync.py", line 518, in thread_handler
    raise exc_info[1]
  File "/usr/local/lib/python3.11/site-packages/django/core/handlers/base.py", line 284, in _get_response_async
    response = await sync_to_async(
               ^^^^^^^^^^^^^^^^^^^^
  File "/usr/local/lib/python3.11/site-packages/asgiref/sync.py", line 468, in __call__
    ret = await asyncio.shield(exec_coro)
          ^^^^^^^^^^^^^^^^^^^^^^^^^^^^^^^
  File "/usr/local/lib/python3.11/concurrent/futures/thread.py", line 58, in run
    result = self.fn(*self.args, **self.kwargs)
             ^^^^^^^^^^^^^^^^^^^^^^^^^^^^^^^^^^
  File "/usr/local/lib/python3.11/site-packages/asgiref/sync.py", line 522, in thread_handler
    return func(*args, **kwargs)
           ^^^^^^^^^^^^^^^^^^^^^
  File "/usr/local/lib/python3.11/site-packages/django/template/response.py", line 114, in render
    self.content = self.rendered_content
                   ^^^^^^^^^^^^^^^^^^^^^
  File "/usr/local/lib/python3.11/site-packages/django/template/response.py", line 92, in rendered_content
    return template.render(context, self._request)
           ^^^^^^^^^^^^^^^^^^^^^^^^^^^^^^^^^^^^^^^
  File "/usr/local/lib/python3.11/site-packages/django/template/backends/django.py", line 107, in render
    return self.template.render(context)
           ^^^^^^^^^^^^^^^^^^^^^^^^^^^^^
  File "/usr/local/lib/python3.11/site-packages/django/template/base.py", line 171, in render
    return self._render(context)
           ^^^^^^^^^^^^^^^^^^^^^
  File "/usr/local/lib/python3.11/site-packages/django/template/base.py", line 163, in _render
    return self.nodelist.render(context)
           ^^^^^^^^^^^^^^^^^^^^^^^^^^^^^
  File "/usr/local/lib/python3.11/site-packages/django/template/base.py", line 1008, in render
    return SafeString("".join([node.render_annotated(context) for node in self]))
                              ^^^^^^^^^^^^^^^^^^^^^^^^^^^^^^^^^^^^^^^^^^^^^^^^^
  File "/usr/local/lib/python3.11/site-packages/django/template/base.py", line 1008, in <listcomp>
    return SafeString("".join([node.render_annotated(context) for node in self]))
                               ^^^^^^^^^^^^^^^^^^^^^^^^^^^^^^
  File "/usr/local/lib/python3.11/site-packages/django/template/base.py", line 969, in render_annotated
    return self.render(context)
           ^^^^^^^^^^^^^^^^^^^^
  File "/usr/local/lib/python3.11/site-packages/django/template/loader_tags.py", line 159, in render
    return compiled_parent._render(context)
           ^^^^^^^^^^^^^^^^^^^^^^^^^^^^^^^^
  File "/usr/local/lib/python3.11/site-packages/django/template/base.py", line 163, in _render
    return self.nodelist.render(context)
           ^^^^^^^^^^^^^^^^^^^^^^^^^^^^^
  File "/usr/local/lib/python3.11/site-packages/django/template/base.py", line 1008, in render
    return SafeString("".join([node.render_annotated(context) for node in self]))
                              ^^^^^^^^^^^^^^^^^^^^^^^^^^^^^^^^^^^^^^^^^^^^^^^^^
  File "/usr/local/lib/python3.11/site-packages/django/template/base.py", line 1008, in <listcomp>
    return SafeString("".join([node.render_annotated(context) for node in self]))
                               ^^^^^^^^^^^^^^^^^^^^^^^^^^^^^^
  File "/usr/local/lib/python3.11/site-packages/django/template/base.py", line 969, in render_annotated
    return self.render(context)
           ^^^^^^^^^^^^^^^^^^^^
  File "/usr/local/lib/python3.11/site-packages/django/template/loader_tags.py", line 159, in render
    return compiled_parent._render(context)
           ^^^^^^^^^^^^^^^^^^^^^^^^^^^^^^^^
  File "/usr/local/lib/python3.11/site-packages/django/template/base.py", line 163, in _render
    return self.nodelist.render(context)
           ^^^^^^^^^^^^^^^^^^^^^^^^^^^^^
  File "/usr/local/lib/python3.11/site-packages/django/template/base.py", line 1008, in render
    return SafeString("".join([node.render_annotated(context) for node in self]))
                              ^^^^^^^^^^^^^^^^^^^^^^^^^^^^^^^^^^^^^^^^^^^^^^^^^
  File "/usr/local/lib/python3.11/site-packages/django/template/base.py", line 1008, in <listcomp>
    return SafeString("".join([node.render_annotated(context) for node in self]))
                               ^^^^^^^^^^^^^^^^^^^^^^^^^^^^^^
  File "/usr/local/lib/python3.11/site-packages/django/template/base.py", line 969, in render_annotated
    return self.render(context)
           ^^^^^^^^^^^^^^^^^^^^
  File "/usr/local/lib/python3.11/site-packages/django/template/loader_tags.py", line 65, in render
    result = block.nodelist.render(context)
             ^^^^^^^^^^^^^^^^^^^^^^^^^^^^^^
  File "/usr/local/lib/python3.11/site-packages/django/template/base.py", line 1008, in render
    return SafeString("".join([node.render_annotated(context) for node in self]))
                              ^^^^^^^^^^^^^^^^^^^^^^^^^^^^^^^^^^^^^^^^^^^^^^^^^
  File "/usr/local/lib/python3.11/site-packages/django/template/base.py", line 1008, in <listcomp>
    return SafeString("".join([node.render_annotated(context) for node in self]))
                               ^^^^^^^^^^^^^^^^^^^^^^^^^^^^^^
  File "/usr/local/lib/python3.11/site-packages/django/template/base.py", line 969, in render_annotated
    return self.render(context)
           ^^^^^^^^^^^^^^^^^^^^
  File "/usr/local/lib/python3.11/site-packages/django/template/loader_tags.py", line 65, in render
    result = block.nodelist.render(context)
             ^^^^^^^^^^^^^^^^^^^^^^^^^^^^^^
  File "/usr/local/lib/python3.11/site-packages/django/template/base.py", line 1008, in render
    return SafeString("".join([node.render_annotated(context) for node in self]))
                              ^^^^^^^^^^^^^^^^^^^^^^^^^^^^^^^^^^^^^^^^^^^^^^^^^
  File "/usr/local/lib/python3.11/site-packages/django/template/base.py", line 1008, in <listcomp>
    return SafeString("".join([node.render_annotated(context) for node in self]))
                               ^^^^^^^^^^^^^^^^^^^^^^^^^^^^^^
  File "/usr/local/lib/python3.11/site-packages/django/template/base.py", line 969, in render_annotated
    return self.render(context)
           ^^^^^^^^^^^^^^^^^^^^
  File "/usr/local/lib/python3.11/site-packages/django/contrib/admin/templatetags/base.py", line 45, in render
    return super().render(context)
           ^^^^^^^^^^^^^^^^^^^^^^^
  File "/usr/local/lib/python3.11/site-packages/django/template/library.py", line 258, in render
    _dict = self.func(*resolved_args, **resolved_kwargs)
            ^^^^^^^^^^^^^^^^^^^^^^^^^^^^^^^^^^^^^^^^^^^^
  File "/usr/local/lib/python3.11/site-packages/django/contrib/admin/templatetags/admin_list.py", line 346, in result_list
    "results": list(results(cl)),
               ^^^^^^^^^^^^^^^^^
  File "/usr/local/lib/python3.11/site-packages/django/contrib/admin/templatetags/admin_list.py", line 322, in results
    yield ResultList(None, items_for_result(cl, res, None))
          ^^^^^^^^^^^^^^^^^^^^^^^^^^^^^^^^^^^^^^^^^^^^^^^^^
  File "/usr/local/lib/python3.11/site-packages/django/contrib/admin/templatetags/admin_list.py", line 313, in __init__
    super().__init__(*items)
  File "/usr/local/lib/python3.11/site-packages/django/contrib/admin/templatetags/admin_list.py", line 218, in items_for_result
    f, attr, value = lookup_field(field_name, result, cl.model_admin)
                     ^^^^^^^^^^^^^^^^^^^^^^^^^^^^^^^^^^^^^^^^^^^^^^^^
  File "/usr/local/lib/python3.11/site-packages/django/contrib/admin/utils.py", line 296, in lookup_field
    value = attr(obj)
            ^^^^^^^^^
  File "/home/accounts/admin.py", line 11, in get_is_online
    if obj.profile.is_online:
       ^^^^^^^^^^^
  File "/usr/local/lib/python3.11/site-packages/django/db/models/fields/related_descriptors.py", line 520, in __get__
    rel_obj = self.get_queryset(instance=instance).get(**filter_args)
              ^^^^^^^^^^^^^^^^^^^^^^^^^^^^^^^^^^^^^^^^^^^^^^^^^^^^^^^
  File "/usr/local/lib/python3.11/site-packages/django/db/models/query.py", line 645, in get
    num = len(clone)
          ^^^^^^^^^^
  File "/usr/local/lib/python3.11/site-packages/django/db/models/query.py", line 382, in __len__
    self._fetch_all()
  File "/usr/local/lib/python3.11/site-packages/django/db/models/query.py", line 1928, in _fetch_all
    self._result_cache = list(self._iterable_class(self))
                         ^^^^^^^^^^^^^^^^^^^^^^^^^^^^^^^^
  File "/usr/local/lib/python3.11/site-packages/django/db/models/query.py", line 91, in __iter__
    results = compiler.execute_sql(
              ^^^^^^^^^^^^^^^^^^^^^
  File "/usr/local/lib/python3.11/site-packages/django/db/models/sql/compiler.py", line 1574, in execute_sql
    cursor.execute(sql, params)
  File "/usr/local/lib/python3.11/site-packages/django/db/backends/utils.py", line 122, in execute
    return super().execute(sql, params)
           ^^^^^^^^^^^^^^^^^^^^^^^^^^^^
  File "/usr/local/lib/python3.11/site-packages/django/db/backends/utils.py", line 79, in execute
    return self._execute_with_wrappers(
           ^^^^^^^^^^^^^^^^^^^^^^^^^^^^
  File "/usr/local/lib/python3.11/site-packages/django/db/backends/utils.py", line 92, in _execute_with_wrappers
    return executor(sql, params, many, context)
           ^^^^^^^^^^^^^^^^^^^^^^^^^^^^^^^^^^^^
  File "/usr/local/lib/python3.11/site-packages/django/db/backends/utils.py", line 100, in _execute
    with self.db.wrap_database_errors:
  File "/usr/local/lib/python3.11/site-packages/django/db/utils.py", line 91, in __exit__
    raise dj_exc_value.with_traceback(traceback) from exc_value
  File "/usr/local/lib/python3.11/site-packages/django/db/backends/utils.py", line 105, in _execute
    return self.cursor.execute(sql, params)
           ^^^^^^^^^^^^^^^^^^^^^^^^^^^^^^^^
django.db.utils.ProgrammingError: column accounts_profile.win_count does not exist
LINE 1: ...profile"."is_online", "accounts_profile"."image", "accounts_...
                                                             ^

ERROR 2025-01-07 18:49:15,608 Internal Server Error: /admin/auth/user/
Traceback (most recent call last):
  File "/usr/local/lib/python3.11/site-packages/django/db/models/options.py", line 676, in get_field
    return self.fields_map[field_name]
           ~~~~~~~~~~~~~~~^^^^^^^^^^^^
KeyError: <function get_is_online at 0x757df215dda0>

During handling of the above exception, another exception occurred:

Traceback (most recent call last):
  File "/usr/local/lib/python3.11/site-packages/django/contrib/admin/utils.py", line 290, in lookup_field
    f = _get_non_gfk_field(opts, name)
        ^^^^^^^^^^^^^^^^^^^^^^^^^^^^^^
  File "/usr/local/lib/python3.11/site-packages/django/contrib/admin/utils.py", line 330, in _get_non_gfk_field
    field = opts.get_field(name)
            ^^^^^^^^^^^^^^^^^^^^
  File "/usr/local/lib/python3.11/site-packages/django/db/models/options.py", line 678, in get_field
    raise FieldDoesNotExist(
django.core.exceptions.FieldDoesNotExist: User has no field named '<function get_is_online at 0x757df215dda0>'

During handling of the above exception, another exception occurred:

Traceback (most recent call last):
  File "/usr/local/lib/python3.11/site-packages/django/db/models/fields/related_descriptors.py", line 512, in __get__
    rel_obj = self.related.get_cached_value(instance)
              ^^^^^^^^^^^^^^^^^^^^^^^^^^^^^^^^^^^^^^^
  File "/usr/local/lib/python3.11/site-packages/django/db/models/fields/mixins.py", line 37, in get_cached_value
    return instance._state.fields_cache[self.cache_name]
           ~~~~~~~~~~~~~~~~~~~~~~~~~~~~^^^^^^^^^^^^^^^^^
KeyError: 'profile'

During handling of the above exception, another exception occurred:

Traceback (most recent call last):
  File "/usr/local/lib/python3.11/site-packages/django/db/backends/utils.py", line 105, in _execute
    return self.cursor.execute(sql, params)
           ^^^^^^^^^^^^^^^^^^^^^^^^^^^^^^^^
psycopg2.errors.UndefinedColumn: column accounts_profile.win_count does not exist
LINE 1: ...profile"."is_online", "accounts_profile"."image", "accounts_...
                                                             ^


The above exception was the direct cause of the following exception:

Traceback (most recent call last):
  File "/usr/local/lib/python3.11/site-packages/asgiref/sync.py", line 518, in thread_handler
    raise exc_info[1]
  File "/usr/local/lib/python3.11/site-packages/django/core/handlers/exception.py", line 42, in inner
    response = await get_response(request)
               ^^^^^^^^^^^^^^^^^^^^^^^^^^^
  File "/usr/local/lib/python3.11/site-packages/asgiref/sync.py", line 518, in thread_handler
    raise exc_info[1]
  File "/usr/local/lib/python3.11/site-packages/django/core/handlers/base.py", line 284, in _get_response_async
    response = await sync_to_async(
               ^^^^^^^^^^^^^^^^^^^^
  File "/usr/local/lib/python3.11/site-packages/asgiref/sync.py", line 468, in __call__
    ret = await asyncio.shield(exec_coro)
          ^^^^^^^^^^^^^^^^^^^^^^^^^^^^^^^
  File "/usr/local/lib/python3.11/concurrent/futures/thread.py", line 58, in run
    result = self.fn(*self.args, **self.kwargs)
             ^^^^^^^^^^^^^^^^^^^^^^^^^^^^^^^^^^
  File "/usr/local/lib/python3.11/site-packages/asgiref/sync.py", line 522, in thread_handler
    return func(*args, **kwargs)
           ^^^^^^^^^^^^^^^^^^^^^
  File "/usr/local/lib/python3.11/site-packages/django/template/response.py", line 114, in render
    self.content = self.rendered_content
                   ^^^^^^^^^^^^^^^^^^^^^
  File "/usr/local/lib/python3.11/site-packages/django/template/response.py", line 92, in rendered_content
    return template.render(context, self._request)
           ^^^^^^^^^^^^^^^^^^^^^^^^^^^^^^^^^^^^^^^
  File "/usr/local/lib/python3.11/site-packages/django/template/backends/django.py", line 107, in render
    return self.template.render(context)
           ^^^^^^^^^^^^^^^^^^^^^^^^^^^^^
  File "/usr/local/lib/python3.11/site-packages/django/template/base.py", line 171, in render
    return self._render(context)
           ^^^^^^^^^^^^^^^^^^^^^
  File "/usr/local/lib/python3.11/site-packages/django/template/base.py", line 163, in _render
    return self.nodelist.render(context)
           ^^^^^^^^^^^^^^^^^^^^^^^^^^^^^
  File "/usr/local/lib/python3.11/site-packages/django/template/base.py", line 1008, in render
    return SafeString("".join([node.render_annotated(context) for node in self]))
                              ^^^^^^^^^^^^^^^^^^^^^^^^^^^^^^^^^^^^^^^^^^^^^^^^^
  File "/usr/local/lib/python3.11/site-packages/django/template/base.py", line 1008, in <listcomp>
    return SafeString("".join([node.render_annotated(context) for node in self]))
                               ^^^^^^^^^^^^^^^^^^^^^^^^^^^^^^
  File "/usr/local/lib/python3.11/site-packages/django/template/base.py", line 969, in render_annotated
    return self.render(context)
           ^^^^^^^^^^^^^^^^^^^^
  File "/usr/local/lib/python3.11/site-packages/django/template/loader_tags.py", line 159, in render
    return compiled_parent._render(context)
           ^^^^^^^^^^^^^^^^^^^^^^^^^^^^^^^^
  File "/usr/local/lib/python3.11/site-packages/django/template/base.py", line 163, in _render
    return self.nodelist.render(context)
           ^^^^^^^^^^^^^^^^^^^^^^^^^^^^^
  File "/usr/local/lib/python3.11/site-packages/django/template/base.py", line 1008, in render
    return SafeString("".join([node.render_annotated(context) for node in self]))
                              ^^^^^^^^^^^^^^^^^^^^^^^^^^^^^^^^^^^^^^^^^^^^^^^^^
  File "/usr/local/lib/python3.11/site-packages/django/template/base.py", line 1008, in <listcomp>
    return SafeString("".join([node.render_annotated(context) for node in self]))
                               ^^^^^^^^^^^^^^^^^^^^^^^^^^^^^^
  File "/usr/local/lib/python3.11/site-packages/django/template/base.py", line 969, in render_annotated
    return self.render(context)
           ^^^^^^^^^^^^^^^^^^^^
  File "/usr/local/lib/python3.11/site-packages/django/template/loader_tags.py", line 159, in render
    return compiled_parent._render(context)
           ^^^^^^^^^^^^^^^^^^^^^^^^^^^^^^^^
  File "/usr/local/lib/python3.11/site-packages/django/template/base.py", line 163, in _render
    return self.nodelist.render(context)
           ^^^^^^^^^^^^^^^^^^^^^^^^^^^^^
  File "/usr/local/lib/python3.11/site-packages/django/template/base.py", line 1008, in render
    return SafeString("".join([node.render_annotated(context) for node in self]))
                              ^^^^^^^^^^^^^^^^^^^^^^^^^^^^^^^^^^^^^^^^^^^^^^^^^
  File "/usr/local/lib/python3.11/site-packages/django/template/base.py", line 1008, in <listcomp>
    return SafeString("".join([node.render_annotated(context) for node in self]))
                               ^^^^^^^^^^^^^^^^^^^^^^^^^^^^^^
  File "/usr/local/lib/python3.11/site-packages/django/template/base.py", line 969, in render_annotated
    return self.render(context)
           ^^^^^^^^^^^^^^^^^^^^
  File "/usr/local/lib/python3.11/site-packages/django/template/loader_tags.py", line 65, in render
    result = block.nodelist.render(context)
             ^^^^^^^^^^^^^^^^^^^^^^^^^^^^^^
  File "/usr/local/lib/python3.11/site-packages/django/template/base.py", line 1008, in render
    return SafeString("".join([node.render_annotated(context) for node in self]))
                              ^^^^^^^^^^^^^^^^^^^^^^^^^^^^^^^^^^^^^^^^^^^^^^^^^
  File "/usr/local/lib/python3.11/site-packages/django/template/base.py", line 1008, in <listcomp>
    return SafeString("".join([node.render_annotated(context) for node in self]))
                               ^^^^^^^^^^^^^^^^^^^^^^^^^^^^^^
  File "/usr/local/lib/python3.11/site-packages/django/template/base.py", line 969, in render_annotated
    return self.render(context)
           ^^^^^^^^^^^^^^^^^^^^
  File "/usr/local/lib/python3.11/site-packages/django/template/loader_tags.py", line 65, in render
    result = block.nodelist.render(context)
             ^^^^^^^^^^^^^^^^^^^^^^^^^^^^^^
  File "/usr/local/lib/python3.11/site-packages/django/template/base.py", line 1008, in render
    return SafeString("".join([node.render_annotated(context) for node in self]))
                              ^^^^^^^^^^^^^^^^^^^^^^^^^^^^^^^^^^^^^^^^^^^^^^^^^
  File "/usr/local/lib/python3.11/site-packages/django/template/base.py", line 1008, in <listcomp>
    return SafeString("".join([node.render_annotated(context) for node in self]))
                               ^^^^^^^^^^^^^^^^^^^^^^^^^^^^^^
  File "/usr/local/lib/python3.11/site-packages/django/template/base.py", line 969, in render_annotated
    return self.render(context)
           ^^^^^^^^^^^^^^^^^^^^
  File "/usr/local/lib/python3.11/site-packages/django/contrib/admin/templatetags/base.py", line 45, in render
    return super().render(context)
           ^^^^^^^^^^^^^^^^^^^^^^^
  File "/usr/local/lib/python3.11/site-packages/django/template/library.py", line 258, in render
    _dict = self.func(*resolved_args, **resolved_kwargs)
            ^^^^^^^^^^^^^^^^^^^^^^^^^^^^^^^^^^^^^^^^^^^^
  File "/usr/local/lib/python3.11/site-packages/django/contrib/admin/templatetags/admin_list.py", line 346, in result_list
    "results": list(results(cl)),
               ^^^^^^^^^^^^^^^^^
  File "/usr/local/lib/python3.11/site-packages/django/contrib/admin/templatetags/admin_list.py", line 322, in results
    yield ResultList(None, items_for_result(cl, res, None))
          ^^^^^^^^^^^^^^^^^^^^^^^^^^^^^^^^^^^^^^^^^^^^^^^^^
  File "/usr/local/lib/python3.11/site-packages/django/contrib/admin/templatetags/admin_list.py", line 313, in __init__
    super().__init__(*items)
  File "/usr/local/lib/python3.11/site-packages/django/contrib/admin/templatetags/admin_list.py", line 218, in items_for_result
    f, attr, value = lookup_field(field_name, result, cl.model_admin)
                     ^^^^^^^^^^^^^^^^^^^^^^^^^^^^^^^^^^^^^^^^^^^^^^^^
  File "/usr/local/lib/python3.11/site-packages/django/contrib/admin/utils.py", line 296, in lookup_field
    value = attr(obj)
            ^^^^^^^^^
  File "/home/accounts/admin.py", line 11, in get_is_online
    if obj.profile.is_online:
       ^^^^^^^^^^^
  File "/usr/local/lib/python3.11/site-packages/django/db/models/fields/related_descriptors.py", line 520, in __get__
    rel_obj = self.get_queryset(instance=instance).get(**filter_args)
              ^^^^^^^^^^^^^^^^^^^^^^^^^^^^^^^^^^^^^^^^^^^^^^^^^^^^^^^
  File "/usr/local/lib/python3.11/site-packages/django/db/models/query.py", line 645, in get
    num = len(clone)
          ^^^^^^^^^^
  File "/usr/local/lib/python3.11/site-packages/django/db/models/query.py", line 382, in __len__
    self._fetch_all()
  File "/usr/local/lib/python3.11/site-packages/django/db/models/query.py", line 1928, in _fetch_all
    self._result_cache = list(self._iterable_class(self))
                         ^^^^^^^^^^^^^^^^^^^^^^^^^^^^^^^^
  File "/usr/local/lib/python3.11/site-packages/django/db/models/query.py", line 91, in __iter__
    results = compiler.execute_sql(
              ^^^^^^^^^^^^^^^^^^^^^
  File "/usr/local/lib/python3.11/site-packages/django/db/models/sql/compiler.py", line 1574, in execute_sql
    cursor.execute(sql, params)
  File "/usr/local/lib/python3.11/site-packages/django/db/backends/utils.py", line 122, in execute
    return super().execute(sql, params)
           ^^^^^^^^^^^^^^^^^^^^^^^^^^^^
  File "/usr/local/lib/python3.11/site-packages/django/db/backends/utils.py", line 79, in execute
    return self._execute_with_wrappers(
           ^^^^^^^^^^^^^^^^^^^^^^^^^^^^
  File "/usr/local/lib/python3.11/site-packages/django/db/backends/utils.py", line 92, in _execute_with_wrappers
    return executor(sql, params, many, context)
           ^^^^^^^^^^^^^^^^^^^^^^^^^^^^^^^^^^^^
  File "/usr/local/lib/python3.11/site-packages/django/db/backends/utils.py", line 100, in _execute
    with self.db.wrap_database_errors:
  File "/usr/local/lib/python3.11/site-packages/django/db/utils.py", line 91, in __exit__
    raise dj_exc_value.with_traceback(traceback) from exc_value
  File "/usr/local/lib/python3.11/site-packages/django/db/backends/utils.py", line 105, in _execute
    return self.cursor.execute(sql, params)
           ^^^^^^^^^^^^^^^^^^^^^^^^^^^^^^^^
django.db.utils.ProgrammingError: column accounts_profile.win_count does not exist
LINE 1: ...profile"."is_online", "accounts_profile"."image", "accounts_...
                                                             ^

ERROR 2025-01-07 18:54:34,475 Internal Server Error: /admin/auth/user/
Traceback (most recent call last):
  File "/usr/local/lib/python3.11/site-packages/django/db/models/options.py", line 676, in get_field
    return self.fields_map[field_name]
           ~~~~~~~~~~~~~~~^^^^^^^^^^^^
KeyError: <function get_is_online at 0x70451b889da0>

During handling of the above exception, another exception occurred:

Traceback (most recent call last):
  File "/usr/local/lib/python3.11/site-packages/django/contrib/admin/utils.py", line 290, in lookup_field
    f = _get_non_gfk_field(opts, name)
        ^^^^^^^^^^^^^^^^^^^^^^^^^^^^^^
  File "/usr/local/lib/python3.11/site-packages/django/contrib/admin/utils.py", line 330, in _get_non_gfk_field
    field = opts.get_field(name)
            ^^^^^^^^^^^^^^^^^^^^
  File "/usr/local/lib/python3.11/site-packages/django/db/models/options.py", line 678, in get_field
    raise FieldDoesNotExist(
django.core.exceptions.FieldDoesNotExist: User has no field named '<function get_is_online at 0x70451b889da0>'

During handling of the above exception, another exception occurred:

Traceback (most recent call last):
  File "/usr/local/lib/python3.11/site-packages/django/db/models/fields/related_descriptors.py", line 512, in __get__
    rel_obj = self.related.get_cached_value(instance)
              ^^^^^^^^^^^^^^^^^^^^^^^^^^^^^^^^^^^^^^^
  File "/usr/local/lib/python3.11/site-packages/django/db/models/fields/mixins.py", line 37, in get_cached_value
    return instance._state.fields_cache[self.cache_name]
           ~~~~~~~~~~~~~~~~~~~~~~~~~~~~^^^^^^^^^^^^^^^^^
KeyError: 'profile'

During handling of the above exception, another exception occurred:

Traceback (most recent call last):
  File "/usr/local/lib/python3.11/site-packages/django/db/backends/utils.py", line 105, in _execute
    return self.cursor.execute(sql, params)
           ^^^^^^^^^^^^^^^^^^^^^^^^^^^^^^^^
psycopg2.errors.UndefinedColumn: column accounts_profile.win_count does not exist
LINE 1: ...profile"."is_online", "accounts_profile"."image", "accounts_...
                                                             ^


The above exception was the direct cause of the following exception:

Traceback (most recent call last):
  File "/usr/local/lib/python3.11/site-packages/asgiref/sync.py", line 518, in thread_handler
    raise exc_info[1]
  File "/usr/local/lib/python3.11/site-packages/django/core/handlers/exception.py", line 42, in inner
    response = await get_response(request)
               ^^^^^^^^^^^^^^^^^^^^^^^^^^^
  File "/usr/local/lib/python3.11/site-packages/asgiref/sync.py", line 518, in thread_handler
    raise exc_info[1]
  File "/usr/local/lib/python3.11/site-packages/django/core/handlers/base.py", line 284, in _get_response_async
    response = await sync_to_async(
               ^^^^^^^^^^^^^^^^^^^^
  File "/usr/local/lib/python3.11/site-packages/asgiref/sync.py", line 468, in __call__
    ret = await asyncio.shield(exec_coro)
          ^^^^^^^^^^^^^^^^^^^^^^^^^^^^^^^
  File "/usr/local/lib/python3.11/concurrent/futures/thread.py", line 58, in run
    result = self.fn(*self.args, **self.kwargs)
             ^^^^^^^^^^^^^^^^^^^^^^^^^^^^^^^^^^
  File "/usr/local/lib/python3.11/site-packages/asgiref/sync.py", line 522, in thread_handler
    return func(*args, **kwargs)
           ^^^^^^^^^^^^^^^^^^^^^
  File "/usr/local/lib/python3.11/site-packages/django/template/response.py", line 114, in render
    self.content = self.rendered_content
                   ^^^^^^^^^^^^^^^^^^^^^
  File "/usr/local/lib/python3.11/site-packages/django/template/response.py", line 92, in rendered_content
    return template.render(context, self._request)
           ^^^^^^^^^^^^^^^^^^^^^^^^^^^^^^^^^^^^^^^
  File "/usr/local/lib/python3.11/site-packages/django/template/backends/django.py", line 107, in render
    return self.template.render(context)
           ^^^^^^^^^^^^^^^^^^^^^^^^^^^^^
  File "/usr/local/lib/python3.11/site-packages/django/template/base.py", line 171, in render
    return self._render(context)
           ^^^^^^^^^^^^^^^^^^^^^
  File "/usr/local/lib/python3.11/site-packages/django/template/base.py", line 163, in _render
    return self.nodelist.render(context)
           ^^^^^^^^^^^^^^^^^^^^^^^^^^^^^
  File "/usr/local/lib/python3.11/site-packages/django/template/base.py", line 1008, in render
    return SafeString("".join([node.render_annotated(context) for node in self]))
                              ^^^^^^^^^^^^^^^^^^^^^^^^^^^^^^^^^^^^^^^^^^^^^^^^^
  File "/usr/local/lib/python3.11/site-packages/django/template/base.py", line 1008, in <listcomp>
    return SafeString("".join([node.render_annotated(context) for node in self]))
                               ^^^^^^^^^^^^^^^^^^^^^^^^^^^^^^
  File "/usr/local/lib/python3.11/site-packages/django/template/base.py", line 969, in render_annotated
    return self.render(context)
           ^^^^^^^^^^^^^^^^^^^^
  File "/usr/local/lib/python3.11/site-packages/django/template/loader_tags.py", line 159, in render
    return compiled_parent._render(context)
           ^^^^^^^^^^^^^^^^^^^^^^^^^^^^^^^^
  File "/usr/local/lib/python3.11/site-packages/django/template/base.py", line 163, in _render
    return self.nodelist.render(context)
           ^^^^^^^^^^^^^^^^^^^^^^^^^^^^^
  File "/usr/local/lib/python3.11/site-packages/django/template/base.py", line 1008, in render
    return SafeString("".join([node.render_annotated(context) for node in self]))
                              ^^^^^^^^^^^^^^^^^^^^^^^^^^^^^^^^^^^^^^^^^^^^^^^^^
  File "/usr/local/lib/python3.11/site-packages/django/template/base.py", line 1008, in <listcomp>
    return SafeString("".join([node.render_annotated(context) for node in self]))
                               ^^^^^^^^^^^^^^^^^^^^^^^^^^^^^^
  File "/usr/local/lib/python3.11/site-packages/django/template/base.py", line 969, in render_annotated
    return self.render(context)
           ^^^^^^^^^^^^^^^^^^^^
  File "/usr/local/lib/python3.11/site-packages/django/template/loader_tags.py", line 159, in render
    return compiled_parent._render(context)
           ^^^^^^^^^^^^^^^^^^^^^^^^^^^^^^^^
  File "/usr/local/lib/python3.11/site-packages/django/template/base.py", line 163, in _render
    return self.nodelist.render(context)
           ^^^^^^^^^^^^^^^^^^^^^^^^^^^^^
  File "/usr/local/lib/python3.11/site-packages/django/template/base.py", line 1008, in render
    return SafeString("".join([node.render_annotated(context) for node in self]))
                              ^^^^^^^^^^^^^^^^^^^^^^^^^^^^^^^^^^^^^^^^^^^^^^^^^
  File "/usr/local/lib/python3.11/site-packages/django/template/base.py", line 1008, in <listcomp>
    return SafeString("".join([node.render_annotated(context) for node in self]))
                               ^^^^^^^^^^^^^^^^^^^^^^^^^^^^^^
  File "/usr/local/lib/python3.11/site-packages/django/template/base.py", line 969, in render_annotated
    return self.render(context)
           ^^^^^^^^^^^^^^^^^^^^
  File "/usr/local/lib/python3.11/site-packages/django/template/loader_tags.py", line 65, in render
    result = block.nodelist.render(context)
             ^^^^^^^^^^^^^^^^^^^^^^^^^^^^^^
  File "/usr/local/lib/python3.11/site-packages/django/template/base.py", line 1008, in render
    return SafeString("".join([node.render_annotated(context) for node in self]))
                              ^^^^^^^^^^^^^^^^^^^^^^^^^^^^^^^^^^^^^^^^^^^^^^^^^
  File "/usr/local/lib/python3.11/site-packages/django/template/base.py", line 1008, in <listcomp>
    return SafeString("".join([node.render_annotated(context) for node in self]))
                               ^^^^^^^^^^^^^^^^^^^^^^^^^^^^^^
  File "/usr/local/lib/python3.11/site-packages/django/template/base.py", line 969, in render_annotated
    return self.render(context)
           ^^^^^^^^^^^^^^^^^^^^
  File "/usr/local/lib/python3.11/site-packages/django/template/loader_tags.py", line 65, in render
    result = block.nodelist.render(context)
             ^^^^^^^^^^^^^^^^^^^^^^^^^^^^^^
  File "/usr/local/lib/python3.11/site-packages/django/template/base.py", line 1008, in render
    return SafeString("".join([node.render_annotated(context) for node in self]))
                              ^^^^^^^^^^^^^^^^^^^^^^^^^^^^^^^^^^^^^^^^^^^^^^^^^
  File "/usr/local/lib/python3.11/site-packages/django/template/base.py", line 1008, in <listcomp>
    return SafeString("".join([node.render_annotated(context) for node in self]))
                               ^^^^^^^^^^^^^^^^^^^^^^^^^^^^^^
  File "/usr/local/lib/python3.11/site-packages/django/template/base.py", line 969, in render_annotated
    return self.render(context)
           ^^^^^^^^^^^^^^^^^^^^
  File "/usr/local/lib/python3.11/site-packages/django/contrib/admin/templatetags/base.py", line 45, in render
    return super().render(context)
           ^^^^^^^^^^^^^^^^^^^^^^^
  File "/usr/local/lib/python3.11/site-packages/django/template/library.py", line 258, in render
    _dict = self.func(*resolved_args, **resolved_kwargs)
            ^^^^^^^^^^^^^^^^^^^^^^^^^^^^^^^^^^^^^^^^^^^^
  File "/usr/local/lib/python3.11/site-packages/django/contrib/admin/templatetags/admin_list.py", line 346, in result_list
    "results": list(results(cl)),
               ^^^^^^^^^^^^^^^^^
  File "/usr/local/lib/python3.11/site-packages/django/contrib/admin/templatetags/admin_list.py", line 322, in results
    yield ResultList(None, items_for_result(cl, res, None))
          ^^^^^^^^^^^^^^^^^^^^^^^^^^^^^^^^^^^^^^^^^^^^^^^^^
  File "/usr/local/lib/python3.11/site-packages/django/contrib/admin/templatetags/admin_list.py", line 313, in __init__
    super().__init__(*items)
  File "/usr/local/lib/python3.11/site-packages/django/contrib/admin/templatetags/admin_list.py", line 218, in items_for_result
    f, attr, value = lookup_field(field_name, result, cl.model_admin)
                     ^^^^^^^^^^^^^^^^^^^^^^^^^^^^^^^^^^^^^^^^^^^^^^^^
  File "/usr/local/lib/python3.11/site-packages/django/contrib/admin/utils.py", line 296, in lookup_field
    value = attr(obj)
            ^^^^^^^^^
  File "/home/accounts/admin.py", line 11, in get_is_online
    if obj.profile.is_online:
       ^^^^^^^^^^^
  File "/usr/local/lib/python3.11/site-packages/django/db/models/fields/related_descriptors.py", line 520, in __get__
    rel_obj = self.get_queryset(instance=instance).get(**filter_args)
              ^^^^^^^^^^^^^^^^^^^^^^^^^^^^^^^^^^^^^^^^^^^^^^^^^^^^^^^
  File "/usr/local/lib/python3.11/site-packages/django/db/models/query.py", line 645, in get
    num = len(clone)
          ^^^^^^^^^^
  File "/usr/local/lib/python3.11/site-packages/django/db/models/query.py", line 382, in __len__
    self._fetch_all()
  File "/usr/local/lib/python3.11/site-packages/django/db/models/query.py", line 1928, in _fetch_all
    self._result_cache = list(self._iterable_class(self))
                         ^^^^^^^^^^^^^^^^^^^^^^^^^^^^^^^^
  File "/usr/local/lib/python3.11/site-packages/django/db/models/query.py", line 91, in __iter__
    results = compiler.execute_sql(
              ^^^^^^^^^^^^^^^^^^^^^
  File "/usr/local/lib/python3.11/site-packages/django/db/models/sql/compiler.py", line 1574, in execute_sql
    cursor.execute(sql, params)
  File "/usr/local/lib/python3.11/site-packages/django/db/backends/utils.py", line 122, in execute
    return super().execute(sql, params)
           ^^^^^^^^^^^^^^^^^^^^^^^^^^^^
  File "/usr/local/lib/python3.11/site-packages/django/db/backends/utils.py", line 79, in execute
    return self._execute_with_wrappers(
           ^^^^^^^^^^^^^^^^^^^^^^^^^^^^
  File "/usr/local/lib/python3.11/site-packages/django/db/backends/utils.py", line 92, in _execute_with_wrappers
    return executor(sql, params, many, context)
           ^^^^^^^^^^^^^^^^^^^^^^^^^^^^^^^^^^^^
  File "/usr/local/lib/python3.11/site-packages/django/db/backends/utils.py", line 100, in _execute
    with self.db.wrap_database_errors:
  File "/usr/local/lib/python3.11/site-packages/django/db/utils.py", line 91, in __exit__
    raise dj_exc_value.with_traceback(traceback) from exc_value
  File "/usr/local/lib/python3.11/site-packages/django/db/backends/utils.py", line 105, in _execute
    return self.cursor.execute(sql, params)
           ^^^^^^^^^^^^^^^^^^^^^^^^^^^^^^^^
django.db.utils.ProgrammingError: column accounts_profile.win_count does not exist
LINE 1: ...profile"."is_online", "accounts_profile"."image", "accounts_...
                                                             ^

ERROR 2025-01-07 18:54:34,475 Internal Server Error: /admin/auth/user/
Traceback (most recent call last):
  File "/usr/local/lib/python3.11/site-packages/django/db/models/options.py", line 676, in get_field
    return self.fields_map[field_name]
           ~~~~~~~~~~~~~~~^^^^^^^^^^^^
KeyError: <function get_is_online at 0x70451b889da0>

During handling of the above exception, another exception occurred:

Traceback (most recent call last):
  File "/usr/local/lib/python3.11/site-packages/django/contrib/admin/utils.py", line 290, in lookup_field
    f = _get_non_gfk_field(opts, name)
        ^^^^^^^^^^^^^^^^^^^^^^^^^^^^^^
  File "/usr/local/lib/python3.11/site-packages/django/contrib/admin/utils.py", line 330, in _get_non_gfk_field
    field = opts.get_field(name)
            ^^^^^^^^^^^^^^^^^^^^
  File "/usr/local/lib/python3.11/site-packages/django/db/models/options.py", line 678, in get_field
    raise FieldDoesNotExist(
django.core.exceptions.FieldDoesNotExist: User has no field named '<function get_is_online at 0x70451b889da0>'

During handling of the above exception, another exception occurred:

Traceback (most recent call last):
  File "/usr/local/lib/python3.11/site-packages/django/db/models/fields/related_descriptors.py", line 512, in __get__
    rel_obj = self.related.get_cached_value(instance)
              ^^^^^^^^^^^^^^^^^^^^^^^^^^^^^^^^^^^^^^^
  File "/usr/local/lib/python3.11/site-packages/django/db/models/fields/mixins.py", line 37, in get_cached_value
    return instance._state.fields_cache[self.cache_name]
           ~~~~~~~~~~~~~~~~~~~~~~~~~~~~^^^^^^^^^^^^^^^^^
KeyError: 'profile'

During handling of the above exception, another exception occurred:

Traceback (most recent call last):
  File "/usr/local/lib/python3.11/site-packages/django/db/backends/utils.py", line 105, in _execute
    return self.cursor.execute(sql, params)
           ^^^^^^^^^^^^^^^^^^^^^^^^^^^^^^^^
psycopg2.errors.UndefinedColumn: column accounts_profile.win_count does not exist
LINE 1: ...profile"."is_online", "accounts_profile"."image", "accounts_...
                                                             ^


The above exception was the direct cause of the following exception:

Traceback (most recent call last):
  File "/usr/local/lib/python3.11/site-packages/asgiref/sync.py", line 518, in thread_handler
    raise exc_info[1]
  File "/usr/local/lib/python3.11/site-packages/django/core/handlers/exception.py", line 42, in inner
    response = await get_response(request)
               ^^^^^^^^^^^^^^^^^^^^^^^^^^^
  File "/usr/local/lib/python3.11/site-packages/asgiref/sync.py", line 518, in thread_handler
    raise exc_info[1]
  File "/usr/local/lib/python3.11/site-packages/django/core/handlers/base.py", line 284, in _get_response_async
    response = await sync_to_async(
               ^^^^^^^^^^^^^^^^^^^^
  File "/usr/local/lib/python3.11/site-packages/asgiref/sync.py", line 468, in __call__
    ret = await asyncio.shield(exec_coro)
          ^^^^^^^^^^^^^^^^^^^^^^^^^^^^^^^
  File "/usr/local/lib/python3.11/concurrent/futures/thread.py", line 58, in run
    result = self.fn(*self.args, **self.kwargs)
             ^^^^^^^^^^^^^^^^^^^^^^^^^^^^^^^^^^
  File "/usr/local/lib/python3.11/site-packages/asgiref/sync.py", line 522, in thread_handler
    return func(*args, **kwargs)
           ^^^^^^^^^^^^^^^^^^^^^
  File "/usr/local/lib/python3.11/site-packages/django/template/response.py", line 114, in render
    self.content = self.rendered_content
                   ^^^^^^^^^^^^^^^^^^^^^
  File "/usr/local/lib/python3.11/site-packages/django/template/response.py", line 92, in rendered_content
    return template.render(context, self._request)
           ^^^^^^^^^^^^^^^^^^^^^^^^^^^^^^^^^^^^^^^
  File "/usr/local/lib/python3.11/site-packages/django/template/backends/django.py", line 107, in render
    return self.template.render(context)
           ^^^^^^^^^^^^^^^^^^^^^^^^^^^^^
  File "/usr/local/lib/python3.11/site-packages/django/template/base.py", line 171, in render
    return self._render(context)
           ^^^^^^^^^^^^^^^^^^^^^
  File "/usr/local/lib/python3.11/site-packages/django/template/base.py", line 163, in _render
    return self.nodelist.render(context)
           ^^^^^^^^^^^^^^^^^^^^^^^^^^^^^
  File "/usr/local/lib/python3.11/site-packages/django/template/base.py", line 1008, in render
    return SafeString("".join([node.render_annotated(context) for node in self]))
                              ^^^^^^^^^^^^^^^^^^^^^^^^^^^^^^^^^^^^^^^^^^^^^^^^^
  File "/usr/local/lib/python3.11/site-packages/django/template/base.py", line 1008, in <listcomp>
    return SafeString("".join([node.render_annotated(context) for node in self]))
                               ^^^^^^^^^^^^^^^^^^^^^^^^^^^^^^
  File "/usr/local/lib/python3.11/site-packages/django/template/base.py", line 969, in render_annotated
    return self.render(context)
           ^^^^^^^^^^^^^^^^^^^^
  File "/usr/local/lib/python3.11/site-packages/django/template/loader_tags.py", line 159, in render
    return compiled_parent._render(context)
           ^^^^^^^^^^^^^^^^^^^^^^^^^^^^^^^^
  File "/usr/local/lib/python3.11/site-packages/django/template/base.py", line 163, in _render
    return self.nodelist.render(context)
           ^^^^^^^^^^^^^^^^^^^^^^^^^^^^^
  File "/usr/local/lib/python3.11/site-packages/django/template/base.py", line 1008, in render
    return SafeString("".join([node.render_annotated(context) for node in self]))
                              ^^^^^^^^^^^^^^^^^^^^^^^^^^^^^^^^^^^^^^^^^^^^^^^^^
  File "/usr/local/lib/python3.11/site-packages/django/template/base.py", line 1008, in <listcomp>
    return SafeString("".join([node.render_annotated(context) for node in self]))
                               ^^^^^^^^^^^^^^^^^^^^^^^^^^^^^^
  File "/usr/local/lib/python3.11/site-packages/django/template/base.py", line 969, in render_annotated
    return self.render(context)
           ^^^^^^^^^^^^^^^^^^^^
  File "/usr/local/lib/python3.11/site-packages/django/template/loader_tags.py", line 159, in render
    return compiled_parent._render(context)
           ^^^^^^^^^^^^^^^^^^^^^^^^^^^^^^^^
  File "/usr/local/lib/python3.11/site-packages/django/template/base.py", line 163, in _render
    return self.nodelist.render(context)
           ^^^^^^^^^^^^^^^^^^^^^^^^^^^^^
  File "/usr/local/lib/python3.11/site-packages/django/template/base.py", line 1008, in render
    return SafeString("".join([node.render_annotated(context) for node in self]))
                              ^^^^^^^^^^^^^^^^^^^^^^^^^^^^^^^^^^^^^^^^^^^^^^^^^
  File "/usr/local/lib/python3.11/site-packages/django/template/base.py", line 1008, in <listcomp>
    return SafeString("".join([node.render_annotated(context) for node in self]))
                               ^^^^^^^^^^^^^^^^^^^^^^^^^^^^^^
  File "/usr/local/lib/python3.11/site-packages/django/template/base.py", line 969, in render_annotated
    return self.render(context)
           ^^^^^^^^^^^^^^^^^^^^
  File "/usr/local/lib/python3.11/site-packages/django/template/loader_tags.py", line 65, in render
    result = block.nodelist.render(context)
             ^^^^^^^^^^^^^^^^^^^^^^^^^^^^^^
  File "/usr/local/lib/python3.11/site-packages/django/template/base.py", line 1008, in render
    return SafeString("".join([node.render_annotated(context) for node in self]))
                              ^^^^^^^^^^^^^^^^^^^^^^^^^^^^^^^^^^^^^^^^^^^^^^^^^
  File "/usr/local/lib/python3.11/site-packages/django/template/base.py", line 1008, in <listcomp>
    return SafeString("".join([node.render_annotated(context) for node in self]))
                               ^^^^^^^^^^^^^^^^^^^^^^^^^^^^^^
  File "/usr/local/lib/python3.11/site-packages/django/template/base.py", line 969, in render_annotated
    return self.render(context)
           ^^^^^^^^^^^^^^^^^^^^
  File "/usr/local/lib/python3.11/site-packages/django/template/loader_tags.py", line 65, in render
    result = block.nodelist.render(context)
             ^^^^^^^^^^^^^^^^^^^^^^^^^^^^^^
  File "/usr/local/lib/python3.11/site-packages/django/template/base.py", line 1008, in render
    return SafeString("".join([node.render_annotated(context) for node in self]))
                              ^^^^^^^^^^^^^^^^^^^^^^^^^^^^^^^^^^^^^^^^^^^^^^^^^
  File "/usr/local/lib/python3.11/site-packages/django/template/base.py", line 1008, in <listcomp>
    return SafeString("".join([node.render_annotated(context) for node in self]))
                               ^^^^^^^^^^^^^^^^^^^^^^^^^^^^^^
  File "/usr/local/lib/python3.11/site-packages/django/template/base.py", line 969, in render_annotated
    return self.render(context)
           ^^^^^^^^^^^^^^^^^^^^
  File "/usr/local/lib/python3.11/site-packages/django/contrib/admin/templatetags/base.py", line 45, in render
    return super().render(context)
           ^^^^^^^^^^^^^^^^^^^^^^^
  File "/usr/local/lib/python3.11/site-packages/django/template/library.py", line 258, in render
    _dict = self.func(*resolved_args, **resolved_kwargs)
            ^^^^^^^^^^^^^^^^^^^^^^^^^^^^^^^^^^^^^^^^^^^^
  File "/usr/local/lib/python3.11/site-packages/django/contrib/admin/templatetags/admin_list.py", line 346, in result_list
    "results": list(results(cl)),
               ^^^^^^^^^^^^^^^^^
  File "/usr/local/lib/python3.11/site-packages/django/contrib/admin/templatetags/admin_list.py", line 322, in results
    yield ResultList(None, items_for_result(cl, res, None))
          ^^^^^^^^^^^^^^^^^^^^^^^^^^^^^^^^^^^^^^^^^^^^^^^^^
  File "/usr/local/lib/python3.11/site-packages/django/contrib/admin/templatetags/admin_list.py", line 313, in __init__
    super().__init__(*items)
  File "/usr/local/lib/python3.11/site-packages/django/contrib/admin/templatetags/admin_list.py", line 218, in items_for_result
    f, attr, value = lookup_field(field_name, result, cl.model_admin)
                     ^^^^^^^^^^^^^^^^^^^^^^^^^^^^^^^^^^^^^^^^^^^^^^^^
  File "/usr/local/lib/python3.11/site-packages/django/contrib/admin/utils.py", line 296, in lookup_field
    value = attr(obj)
            ^^^^^^^^^
  File "/home/accounts/admin.py", line 11, in get_is_online
    if obj.profile.is_online:
       ^^^^^^^^^^^
  File "/usr/local/lib/python3.11/site-packages/django/db/models/fields/related_descriptors.py", line 520, in __get__
    rel_obj = self.get_queryset(instance=instance).get(**filter_args)
              ^^^^^^^^^^^^^^^^^^^^^^^^^^^^^^^^^^^^^^^^^^^^^^^^^^^^^^^
  File "/usr/local/lib/python3.11/site-packages/django/db/models/query.py", line 645, in get
    num = len(clone)
          ^^^^^^^^^^
  File "/usr/local/lib/python3.11/site-packages/django/db/models/query.py", line 382, in __len__
    self._fetch_all()
  File "/usr/local/lib/python3.11/site-packages/django/db/models/query.py", line 1928, in _fetch_all
    self._result_cache = list(self._iterable_class(self))
                         ^^^^^^^^^^^^^^^^^^^^^^^^^^^^^^^^
  File "/usr/local/lib/python3.11/site-packages/django/db/models/query.py", line 91, in __iter__
    results = compiler.execute_sql(
              ^^^^^^^^^^^^^^^^^^^^^
  File "/usr/local/lib/python3.11/site-packages/django/db/models/sql/compiler.py", line 1574, in execute_sql
    cursor.execute(sql, params)
  File "/usr/local/lib/python3.11/site-packages/django/db/backends/utils.py", line 122, in execute
    return super().execute(sql, params)
           ^^^^^^^^^^^^^^^^^^^^^^^^^^^^
  File "/usr/local/lib/python3.11/site-packages/django/db/backends/utils.py", line 79, in execute
    return self._execute_with_wrappers(
           ^^^^^^^^^^^^^^^^^^^^^^^^^^^^
  File "/usr/local/lib/python3.11/site-packages/django/db/backends/utils.py", line 92, in _execute_with_wrappers
    return executor(sql, params, many, context)
           ^^^^^^^^^^^^^^^^^^^^^^^^^^^^^^^^^^^^
  File "/usr/local/lib/python3.11/site-packages/django/db/backends/utils.py", line 100, in _execute
    with self.db.wrap_database_errors:
  File "/usr/local/lib/python3.11/site-packages/django/db/utils.py", line 91, in __exit__
    raise dj_exc_value.with_traceback(traceback) from exc_value
  File "/usr/local/lib/python3.11/site-packages/django/db/backends/utils.py", line 105, in _execute
    return self.cursor.execute(sql, params)
           ^^^^^^^^^^^^^^^^^^^^^^^^^^^^^^^^
django.db.utils.ProgrammingError: column accounts_profile.win_count does not exist
LINE 1: ...profile"."is_online", "accounts_profile"."image", "accounts_...
                                                             ^

WARNING 2025-01-07 18:55:41,425 Forbidden: /accounts/users/me/get-myname/
WARNING 2025-01-07 18:55:41,425 Forbidden: /accounts/users/me/get-myname/
WARNING 2025-01-07 18:55:55,477 Forbidden: /accounts/users/me/get-myname/
WARNING 2025-01-07 18:55:55,477 Forbidden: /accounts/users/me/get-myname/
WARNING 2025-01-07 18:59:56,148 Forbidden: /accounts/users/me/get-myname/
WARNING 2025-01-07 18:59:56,148 Forbidden: /accounts/users/me/get-myname/
